5:return {{["name"] = "default:wood", ["y"] = 0, ["z"] = 0, ["x"] = 0}, {["name"] = "default:wood", ["y"] = 0, ["z"] = 1, ["x"] = 0}, {["name"] = "wool:blue", ["y"] = 0, ["z"] = 3, ["x"] = 0}, {["name"] = "wool:blue", ["y"] = 0, ["z"] = 4, ["x"] = 0}, {["name"] = "wool:blue", ["y"] = 0, ["z"] = 5, ["x"] = 0}, {["name"] = "wool:blue", ["y"] = 0, ["z"] = 6, ["x"] = 0}, {["name"] = "wool:blue", ["y"] = 0, ["z"] = 7, ["x"] = 0}, {["name"] = "wool:blue", ["y"] = 0, ["z"] = 8, ["x"] = 0}, {["name"] = "wool:green", ["y"] = 0, ["z"] = 13, ["x"] = 0}, {["name"] = "wool:green", ["y"] = 0, ["z"] = 14, ["x"] = 0}, {["name"] = "default:wood", ["y"] = 0, ["z"] = 15, ["x"] = 0}, {["name"] = "default:wood", ["y"] = 0, ["z"] = 16, ["x"] = 0}, {["name"] = "default:wood", ["y"] = 1, ["z"] = 0, ["x"] = 0}, {["name"] = "default:wood", ["y"] = 1, ["z"] = 1, ["x"] = 0}, {["name"] = "wool:blue", ["y"] = 1, ["z"] = 3, ["x"] = 0}, {["name"] = "wool:blue", ["y"] = 1, ["z"] = 4, ["x"] = 0}, {["name"] = "wool:blue", ["y"] = 1, ["z"] = 5, ["x"] = 0}, {["name"] = "wool:blue", ["y"] = 1, ["z"] = 6, ["x"] = 0}, {["name"] = "wool:blue", ["y"] = 1, ["z"] = 7, ["x"] = 0}, {["name"] = "wool:blue", ["y"] = 1, ["z"] = 8, ["x"] = 0}, {["name"] = "wool:green", ["y"] = 1, ["z"] = 12, ["x"] = 0}, {["name"] = "wool:green", ["y"] = 1, ["z"] = 13, ["x"] = 0}, {["name"] = "wool:green", ["y"] = 1, ["z"] = 14, ["x"] = 0}, {["name"] = "default:wood", ["y"] = 1, ["z"] = 15, ["x"] = 0}, {["name"] = "default:wood", ["y"] = 1, ["z"] = 16, ["x"] = 0}, {["name"] = "default:wood", ["y"] = 2, ["z"] = 0, ["x"] = 0}, {["name"] = "default:wood", ["y"] = 2, ["z"] = 1, ["x"] = 0}, {["name"] = "wool:blue", ["y"] = 2, ["z"] = 3, ["x"] = 0}, {["name"] = "wool:blue", ["y"] = 2, ["z"] = 4, ["x"] = 0}, {["name"] = "wool:blue", ["y"] = 2, ["z"] = 5, ["x"] = 0}, {["name"] = "wool:blue", ["y"] = 2, ["z"] = 6, ["x"] = 0}, {["name"] = "wool:blue", ["y"] = 2, ["z"] = 7, ["x"] = 0}, {["name"] = "wool:blue", ["y"] = 2, ["z"] = 8, ["x"] = 0}, {["name"] = "wool:green", ["y"] = 2, ["z"] = 11, ["x"] = 0}, {["name"] = "wool:green", ["y"] = 2, ["z"] = 12, ["x"] = 0}, {["name"] = "wool:green", ["y"] = 2, ["z"] = 13, ["x"] = 0}, {["name"] = "default:wood", ["y"] = 2, ["z"] = 15, ["x"] = 0}, {["name"] = "default:wood", ["y"] = 2, ["z"] = 16, ["x"] = 0}, {["name"] = "default:wood", ["y"] = 3, ["z"] = 0, ["x"] = 0}, {["name"] = "default:wood", ["y"] = 3, ["z"] = 1, ["x"] = 0}, {["name"] = "wool:red", ["y"] = 3, ["z"] = 3, ["x"] = 0}, {["name"] = "wool:red", ["y"] = 3, ["z"] = 4, ["x"] = 0}, {["name"] = "wool:red", ["y"] = 3, ["z"] = 5, ["x"] = 0}, {["name"] = "wool:orange", ["y"] = 3, ["z"] = 6, ["x"] = 0}, {["name"] = "wool:white", ["y"] = 3, ["z"] = 7, ["x"] = 0}, {["name"] = "wool:orange", ["y"] = 3, ["z"] = 8, ["x"] = 0}, {["name"] = "wool:green", ["y"] = 3, ["z"] = 10, ["x"] = 0}, {["name"] = "wool:green", ["y"] = 3, ["z"] = 11, ["x"] = 0}, {["name"] = "wool:green", ["y"] = 3, ["z"] = 12, ["x"] = 0}, {["name"] = "default:wood", ["y"] = 3, ["z"] = 15, ["x"] = 0}, {["name"] = "default:wood", ["y"] = 3, ["z"] = 16, ["x"] = 0}, {["name"] = "default:wood", ["y"] = 4, ["z"] = 0, ["x"] = 0}, {["name"] = "default:wood", ["y"] = 4, ["z"] = 1, ["x"] = 0}, {["name"] = "wool:red", ["y"] = 4, ["z"] = 3, ["x"] = 0}, {["name"] = "wool:red", ["y"] = 4, ["z"] = 4, ["x"] = 0}, {["name"] = "wool:red", ["y"] = 4, ["z"] = 5, ["x"] = 0}, {["name"] = "wool:orange", ["y"] = 4, ["z"] = 6, ["x"] = 0}, {["name"] = "wool:white", ["y"] = 4, ["z"] = 7, ["x"] = 0}, {["name"] = "wool:orange", ["y"] = 4, ["z"] = 8, ["x"] = 0}, {["name"] = "wool:green", ["y"] = 4, ["z"] = 9, ["x"] = 0}, {["name"] = "wool:green", ["y"] = 4, ["z"] = 10, ["x"] = 0}, {["name"] = "wool:green", ["y"] = 4, ["z"] = 11, ["x"] = 0}, {["name"] = "default:wood", ["y"] = 4, ["z"] = 15, ["x"] = 0}, {["name"] = "default:wood", ["y"] = 4, ["z"] = 16, ["x"] = 0}, {["name"] = "default:wood", ["y"] = 5, ["z"] = 0, ["x"] = 0}, {["name"] = "default:wood", ["y"] = 5, ["z"] = 1, ["x"] = 0}, {["name"] = "wool:red", ["y"] = 5, ["z"] = 3, ["x"] = 0}, {["name"] = "wool:red", ["y"] = 5, ["z"] = 4, ["x"] = 0}, {["name"] = "wool:red", ["y"] = 5, ["z"] = 5, ["x"] = 0}, {["name"] = "wool:orange", ["y"] = 5, ["z"] = 6, ["x"] = 0}, {["name"] = "wool:white", ["y"] = 5, ["z"] = 7, ["x"] = 0}, {["name"] = "wool:orange", ["y"] = 5, ["z"] = 8, ["x"] = 0}, {["name"] = "wool:green", ["y"] = 5, ["z"] = 9, ["x"] = 0}, {["name"] = "wool:green", ["y"] = 5, ["z"] = 10, ["x"] = 0}, {["name"] = "default:wood", ["y"] = 5, ["z"] = 15, ["x"] = 0}, {["name"] = "default:wood", ["y"] = 5, ["z"] = 16, ["x"] = 0}, {["name"] = "default:wood", ["y"] = 6, ["z"] = 0, ["x"] = 0}, {["name"] = "default:wood", ["y"] = 6, ["z"] = 1, ["x"] = 0}, {["name"] = "wool:red", ["y"] = 6, ["z"] = 3, ["x"] = 0}, {["name"] = "wool:red", ["y"] = 6, ["z"] = 4, ["x"] = 0}, {["name"] = "wool:red", ["y"] = 6, ["z"] = 5, ["x"] = 0}, {["name"] = "wool:orange", ["y"] = 6, ["z"] = 6, ["x"] = 0}, {["name"] = "wool:white", ["y"] = 6, ["z"] = 7, ["x"] = 0}, {["name"] = "wool:orange", ["y"] = 6, ["z"] = 8, ["x"] = 0}, {["name"] = "default:wood", ["y"] = 6, ["z"] = 15, ["x"] = 0}, {["name"] = "default:wood", ["y"] = 6, ["z"] = 16, ["x"] = 0}, {["name"] = "default:wood", ["y"] = 7, ["z"] = 0, ["x"] = 0}, {["name"] = "default:wood", ["y"] = 7, ["z"] = 1, ["x"] = 0}, {["name"] = "wool:red", ["y"] = 7, ["z"] = 3, ["x"] = 0}, {["name"] = "wool:red", ["y"] = 7, ["z"] = 4, ["x"] = 0}, {["name"] = "wool:red", ["y"] = 7, ["z"] = 5, ["x"] = 0}, {["name"] = "wool:orange", ["y"] = 7, ["z"] = 6, ["x"] = 0}, {["name"] = "wool:white", ["y"] = 7, ["z"] = 7, ["x"] = 0}, {["name"] = "wool:orange", ["y"] = 7, ["z"] = 8, ["x"] = 0}, {["name"] = "default:wood", ["y"] = 7, ["z"] = 15, ["x"] = 0}, {["name"] = "default:wood", ["y"] = 7, ["z"] = 16, ["x"] = 0}, {["name"] = "default:wood", ["y"] = 8, ["z"] = 0, ["x"] = 0}, {["name"] = "default:wood", ["y"] = 8, ["z"] = 1, ["x"] = 0}, {["name"] = "wool:red", ["y"] = 8, ["z"] = 3, ["x"] = 0}, {["name"] = "wool:red", ["y"] = 8, ["z"] = 4, ["x"] = 0}, {["name"] = "wool:red", ["y"] = 8, ["z"] = 5, ["x"] = 0}, {["name"] = "wool:orange", ["y"] = 8, ["z"] = 6, ["x"] = 0}, {["name"] = "wool:white", ["y"] = 8, ["z"] = 7, ["x"] = 0}, {["name"] = "wool:orange", ["y"] = 8, ["z"] = 8, ["x"] = 0}, {["name"] = "default:wood", ["y"] = 8, ["z"] = 15, ["x"] = 0}, {["name"] = "default:wood", ["y"] = 8, ["z"] = 16, ["x"] = 0}, {["name"] = "default:wood", ["y"] = 9, ["z"] = 0, ["x"] = 0}, {["name"] = "default:wood", ["y"] = 9, ["z"] = 1, ["x"] = 0}, {["name"] = "default:wood", ["y"] = 9, ["z"] = 15, ["x"] = 0}, {["name"] = "default:wood", ["y"] = 9, ["z"] = 16, ["x"] = 0}, {["name"] = "default:wood", ["y"] = 10, ["z"] = 0, ["x"] = 0}, {["name"] = "default:wood", ["y"] = 10, ["z"] = 1, ["x"] = 0}, {["name"] = "default:wood", ["y"] = 10, ["z"] = 2, ["x"] = 0}, {["name"] = "default:wood", ["y"] = 10, ["z"] = 3, ["x"] = 0}, {["name"] = "default:wood", ["y"] = 10, ["z"] = 4, ["x"] = 0}, {["name"] = "default:wood", ["y"] = 10, ["z"] = 5, ["x"] = 0}, {["name"] = "default:wood", ["y"] = 10, ["z"] = 6, ["x"] = 0}, {["name"] = "default:wood", ["y"] = 10, ["z"] = 7, ["x"] = 0}, {["name"] = "default:wood", ["y"] = 10, ["z"] = 8, ["x"] = 0}, {["name"] = "default:wood", ["y"] = 10, ["z"] = 9, ["x"] = 0}, {["name"] = "default:wood", ["y"] = 10, ["z"] = 10, ["x"] = 0}, {["name"] = "default:wood", ["y"] = 10, ["z"] = 11, ["x"] = 0}, {["name"] = "default:wood", ["y"] = 10, ["z"] = 12, ["x"] = 0}, {["name"] = "default:wood", ["y"] = 10, ["z"] = 13, ["x"] = 0}, {["name"] = "default:wood", ["y"] = 10, ["z"] = 14, ["x"] = 0}, {["name"] = "default:wood", ["y"] = 10, ["z"] = 15, ["x"] = 0}, {["name"] = "default:wood", ["y"] = 10, ["z"] = 16, ["x"] = 0}, {["name"] = "default:wood", ["y"] = 0, ["z"] = 0, ["x"] = 1}, {["name"] = "default:wood", ["y"] = 0, ["z"] = 1, ["x"] = 1}, {["name"] = "wool:blue", ["y"] = 0, ["z"] = 3, ["x"] = 1}, {["name"] = "wool:blue", ["y"] = 0, ["z"] = 4, ["x"] = 1}, {["name"] = "wool:blue", ["y"] = 0, ["z"] = 5, ["x"] = 1}, {["name"] = "wool:blue", ["y"] = 0, ["z"] = 6, ["x"] = 1}, {["name"] = "wool:blue", ["y"] = 0, ["z"] = 7, ["x"] = 1}, {["name"] = "wool:blue", ["y"] = 0, ["z"] = 8, ["x"] = 1}, {["name"] = "wool:green", ["y"] = 0, ["z"] = 13, ["x"] = 1}, {["name"] = "wool:white", ["y"] = 0, ["z"] = 14, ["x"] = 1}, {["name"] = "default:wood", ["y"] = 0, ["z"] = 15, ["x"] = 1}, {["name"] = "default:wood", ["y"] = 0, ["z"] = 16, ["x"] = 1}, {["name"] = "default:wood", ["y"] = 1, ["z"] = 0, ["x"] = 1}, {["name"] = "default:wood", ["y"] = 1, ["z"] = 1, ["x"] = 1}, {["name"] = "wool:white", ["y"] = 1, ["z"] = 3, ["x"] = 1}, {["name"] = "wool:white", ["y"] = 1, ["z"] = 4, ["x"] = 1}, {["name"] = "wool:white", ["y"] = 1, ["z"] = 5, ["x"] = 1}, {["name"] = "wool:white", ["y"] = 1, ["z"] = 6, ["x"] = 1}, {["name"] = "wool:white", ["y"] = 1, ["z"] = 7, ["x"] = 1}, {["name"] = "wool:white", ["y"] = 1, ["z"] = 8, ["x"] = 1}, {["name"] = "wool:green", ["y"] = 1, ["z"] = 12, ["x"] = 1}, {["name"] = "wool:white", ["y"] = 1, ["z"] = 13, ["x"] = 1}, {["name"] = "wool:green", ["y"] = 1, ["z"] = 14, ["x"] = 1}, {["name"] = "default:wood", ["y"] = 1, ["z"] = 15, ["x"] = 1}, {["name"] = "default:wood", ["y"] = 1, ["z"] = 16, ["x"] = 1}, {["name"] = "default:wood", ["y"] = 2, ["z"] = 0, ["x"] = 1}, {["name"] = "default:wood", ["y"] = 2, ["z"] = 1, ["x"] = 1}, {["name"] = "wool:blue", ["y"] = 2, ["z"] = 3, ["x"] = 1}, {["name"] = "wool:blue", ["y"] = 2, ["z"] = 4, ["x"] = 1}, {["name"] = "wool:blue", ["y"] = 2, ["z"] = 5, ["x"] = 1}, {["name"] = "wool:blue", ["y"] = 2, ["z"] = 6, ["x"] = 1}, {["name"] = "wool:blue", ["y"] = 2, ["z"] = 7, ["x"] = 1}, {["name"] = "wool:blue", ["y"] = 2, ["z"] = 8, ["x"] = 1}, {["name"] = "wool:green", ["y"] = 2, ["z"] = 11, ["x"] = 1}, {["name"] = "wool:white", ["y"] = 2, ["z"] = 12, ["x"] = 1}, {["name"] = "wool:green", ["y"] = 2, ["z"] = 13, ["x"] = 1}, {["name"] = "default:wood", ["y"] = 2, ["z"] = 15, ["x"] = 1}, {["name"] = "default:wood", ["y"] = 2, ["z"] = 16, ["x"] = 1}, {["name"] = "default:wood", ["y"] = 3, ["z"] = 0, ["x"] = 1}, {["name"] = "default:wood", ["y"] = 3, ["z"] = 1, ["x"] = 1}, {["name"] = "wool:red", ["y"] = 3, ["z"] = 3, ["x"] = 1}, {["name"] = "wool:white", ["y"] = 3, ["z"] = 4, ["x"] = 1}, {["name"] = "wool:red", ["y"] = 3, ["z"] = 5, ["x"] = 1}, {["name"] = "wool:orange", ["y"] = 3, ["z"] = 6, ["x"] = 1}, {["name"] = "wool:white", ["y"] = 3, ["z"] = 7, ["x"] = 1}, {["name"] = "wool:orange", ["y"] = 3, ["z"] = 8, ["x"] = 1}, {["name"] = "wool:green", ["y"] = 3, ["z"] = 10, ["x"] = 1}, {["name"] = "wool:white", ["y"] = 3, ["z"] = 11, ["x"] = 1}, {["name"] = "wool:green", ["y"] = 3, ["z"] = 12, ["x"] = 1}, {["name"] = "default:wood", ["y"] = 3, ["z"] = 15, ["x"] = 1}, {["name"] = "default:wood", ["y"] = 3, ["z"] = 16, ["x"] = 1}, {["name"] = "default:wood", ["y"] = 4, ["z"] = 0, ["x"] = 1}, {["name"] = "default:wood", ["y"] = 4, ["z"] = 1, ["x"] = 1}, {["name"] = "wool:red", ["y"] = 4, ["z"] = 3, ["x"] = 1}, {["name"] = "wool:white", ["y"] = 4, ["z"] = 4, ["x"] = 1}, {["name"] = "wool:red", ["y"] = 4, ["z"] = 5, ["x"] = 1}, {["name"] = "wool:orange", ["y"] = 4, ["z"] = 6, ["x"] = 1}, {["name"] = "wool:white", ["y"] = 4, ["z"] = 7, ["x"] = 1}, {["name"] = "wool:orange", ["y"] = 4, ["z"] = 8, ["x"] = 1}, {["name"] = "wool:green", ["y"] = 4, ["z"] = 9, ["x"] = 1}, {["name"] = "wool:white", ["y"] = 4, ["z"] = 10, ["x"] = 1}, {["name"] = "wool:green", ["y"] = 4, ["z"] = 11, ["x"] = 1}, {["name"] = "default:wood", ["y"] = 4, ["z"] = 15, ["x"] = 1}, {["name"] = "default:wood", ["y"] = 4, ["z"] = 16, ["x"] = 1}, {["name"] = "default:wood", ["y"] = 5, ["z"] = 0, ["x"] = 1}, {["name"] = "default:wood", ["y"] = 5, ["z"] = 1, ["x"] = 1}, {["name"] = "wool:red", ["y"] = 5, ["z"] = 3, ["x"] = 1}, {["name"] = "wool:white", ["y"] = 5, ["z"] = 4, ["x"] = 1}, {["name"] = "wool:red", ["y"] = 5, ["z"] = 5, ["x"] = 1}, {["name"] = "wool:orange", ["y"] = 5, ["z"] = 6, ["x"] = 1}, {["name"] = "wool:white", ["y"] = 5, ["z"] = 7, ["x"] = 1}, {["name"] = "wool:orange", ["y"] = 5, ["z"] = 8, ["x"] = 1}, {["name"] = "wool:green", ["y"] = 5, ["z"] = 9, ["x"] = 1}, {["name"] = "wool:green", ["y"] = 5, ["z"] = 10, ["x"] = 1}, {["name"] = "default:wood", ["y"] = 5, ["z"] = 15, ["x"] = 1}, {["name"] = "default:wood", ["y"] = 5, ["z"] = 16, ["x"] = 1}, {["name"] = "default:wood", ["y"] = 6, ["z"] = 0, ["x"] = 1}, {["name"] = "default:wood", ["y"] = 6, ["z"] = 1, ["x"] = 1}, {["name"] = "wool:red", ["y"] = 6, ["z"] = 3, ["x"] = 1}, {["name"] = "wool:white", ["y"] = 6, ["z"] = 4, ["x"] = 1}, {["name"] = "wool:red", ["y"] = 6, ["z"] = 5, ["x"] = 1}, {["name"] = "wool:orange", ["y"] = 6, ["z"] = 6, ["x"] = 1}, {["name"] = "wool:white", ["y"] = 6, ["z"] = 7, ["x"] = 1}, {["name"] = "wool:orange", ["y"] = 6, ["z"] = 8, ["x"] = 1}, {["name"] = "default:wood", ["y"] = 6, ["z"] = 15, ["x"] = 1}, {["name"] = "default:wood", ["y"] = 6, ["z"] = 16, ["x"] = 1}, {["name"] = "default:wood", ["y"] = 7, ["z"] = 0, ["x"] = 1}, {["name"] = "default:wood", ["y"] = 7, ["z"] = 1, ["x"] = 1}, {["name"] = "wool:red", ["y"] = 7, ["z"] = 3, ["x"] = 1}, {["name"] = "wool:white", ["y"] = 7, ["z"] = 4, ["x"] = 1}, {["name"] = "wool:red", ["y"] = 7, ["z"] = 5, ["x"] = 1}, {["name"] = "wool:orange", ["y"] = 7, ["z"] = 6, ["x"] = 1}, {["name"] = "wool:white", ["y"] = 7, ["z"] = 7, ["x"] = 1}, {["name"] = "wool:orange", ["y"] = 7, ["z"] = 8, ["x"] = 1}, {["name"] = "default:wood", ["y"] = 7, ["z"] = 15, ["x"] = 1}, {["name"] = "default:wood", ["y"] = 7, ["z"] = 16, ["x"] = 1}, {["name"] = "default:wood", ["y"] = 8, ["z"] = 0, ["x"] = 1}, {["name"] = "default:wood", ["y"] = 8, ["z"] = 1, ["x"] = 1}, {["name"] = "wool:red", ["y"] = 8, ["z"] = 3, ["x"] = 1}, {["name"] = "wool:white", ["y"] = 8, ["z"] = 4, ["x"] = 1}, {["name"] = "wool:red", ["y"] = 8, ["z"] = 5, ["x"] = 1}, {["name"] = "wool:orange", ["y"] = 8, ["z"] = 6, ["x"] = 1}, {["name"] = "wool:white", ["y"] = 8, ["z"] = 7, ["x"] = 1}, {["name"] = "wool:orange", ["y"] = 8, ["z"] = 8, ["x"] = 1}, {["name"] = "default:wood", ["y"] = 8, ["z"] = 15, ["x"] = 1}, {["name"] = "default:wood", ["y"] = 8, ["z"] = 16, ["x"] = 1}, {["name"] = "default:wood", ["y"] = 9, ["z"] = 0, ["x"] = 1}, {["name"] = "default:wood", ["y"] = 9, ["z"] = 1, ["x"] = 1}, {["name"] = "default:wood", ["y"] = 9, ["z"] = 15, ["x"] = 1}, {["name"] = "default:wood", ["y"] = 9, ["z"] = 16, ["x"] = 1}, {["name"] = "default:wood", ["y"] = 10, ["z"] = 0, ["x"] = 1}, {["name"] = "default:wood", ["y"] = 10, ["z"] = 1, ["x"] = 1}, {["name"] = "default:wood", ["y"] = 10, ["z"] = 2, ["x"] = 1}, {["name"] = "default:wood", ["y"] = 10, ["z"] = 3, ["x"] = 1}, {["name"] = "default:wood", ["y"] = 10, ["z"] = 4, ["x"] = 1}, {["name"] = "default:wood", ["y"] = 10, ["z"] = 5, ["x"] = 1}, {["name"] = "default:wood", ["y"] = 10, ["z"] = 6, ["x"] = 1}, {["name"] = "default:wood", ["y"] = 10, ["z"] = 7, ["x"] = 1}, {["name"] = "default:wood", ["y"] = 10, ["z"] = 8, ["x"] = 1}, {["name"] = "default:wood", ["y"] = 10, ["z"] = 9, ["x"] = 1}, {["name"] = "default:wood", ["y"] = 10, ["z"] = 10, ["x"] = 1}, {["name"] = "default:wood", ["y"] = 10, ["z"] = 11, ["x"] = 1}, {["name"] = "default:wood", ["y"] = 10, ["z"] = 12, ["x"] = 1}, {["name"] = "default:wood", ["y"] = 10, ["z"] = 13, ["x"] = 1}, {["name"] = "default:wood", ["y"] = 10, ["z"] = 14, ["x"] = 1}, {["name"] = "default:wood", ["y"] = 10, ["z"] = 15, ["x"] = 1}, {["name"] = "default:wood", ["y"] = 10, ["z"] = 16, ["x"] = 1}, {["name"] = "wool:dark_green", ["y"] = 11, ["z"] = 14, ["x"] = 1}, {["name"] = "wool:dark_green", ["y"] = 11, ["z"] = 15, ["x"] = 1}, {["name"] = "wool:yellow", ["y"] = 12, ["z"] = 14, ["x"] = 1}, {["name"] = "wool:yellow", ["y"] = 12, ["z"] = 15, ["x"] = 1}, {["name"] = "wool:yellow", ["y"] = 13, ["z"] = 14, ["x"] = 1}, {["name"] = "wool:yellow", ["y"] = 13, ["z"] = 15, ["x"] = 1}, {["name"] = "wool:yellow", ["y"] = 14, ["z"] = 14, ["x"] = 1}, {["name"] = "wool:yellow", ["y"] = 14, ["z"] = 15, ["x"] = 1}, {["name"] = "wool:yellow", ["y"] = 15, ["z"] = 14, ["x"] = 1}, {["name"] = "wool:yellow", ["y"] = 15, ["z"] = 15, ["x"] = 1}, {["name"] = "wool:dark_green", ["y"] = 16, ["z"] = 14, ["x"] = 1}, {["name"] = "wool:dark_green", ["y"] = 16, ["z"] = 15, ["x"] = 1}, {["name"] = "wool:blue", ["y"] = 0, ["z"] = 3, ["x"] = 2}, {["name"] = "wool:blue", ["y"] = 0, ["z"] = 4, ["x"] = 2}, {["name"] = "wool:blue", ["y"] = 0, ["z"] = 5, ["x"] = 2}, {["name"] = "wool:blue", ["y"] = 0, ["z"] = 6, ["x"] = 2}, {["name"] = "wool:blue", ["y"] = 0, ["z"] = 7, ["x"] = 2}, {["name"] = "wool:blue", ["y"] = 0, ["z"] = 8, ["x"] = 2}, {["name"] = "wool:green", ["y"] = 0, ["z"] = 13, ["x"] = 2}, {["name"] = "wool:white", ["y"] = 0, ["z"] = 14, ["x"] = 2}, {["name"] = "wool:green", ["y"] = 0, ["z"] = 15, ["x"] = 2}, {["name"] = "wool:white", ["y"] = 1, ["z"] = 3, ["x"] = 2}, {["name"] = "wool:white", ["y"] = 1, ["z"] = 4, ["x"] = 2}, {["name"] = "wool:white", ["y"] = 1, ["z"] = 5, ["x"] = 2}, {["name"] = "wool:white", ["y"] = 1, ["z"] = 6, ["x"] = 2}, {["name"] = "wool:white", ["y"] = 1, ["z"] = 7, ["x"] = 2}, {["name"] = "wool:white", ["y"] = 1, ["z"] = 8, ["x"] = 2}, {["name"] = "wool:green", ["y"] = 1, ["z"] = 12, ["x"] = 2}, {["name"] = "wool:white", ["y"] = 1, ["z"] = 13, ["x"] = 2}, {["name"] = "wool:green", ["y"] = 1, ["z"] = 14, ["x"] = 2}, {["name"] = "wool:blue", ["y"] = 2, ["z"] = 3, ["x"] = 2}, {["name"] = "wool:blue", ["y"] = 2, ["z"] = 4, ["x"] = 2}, {["name"] = "wool:blue", ["y"] = 2, ["z"] = 5, ["x"] = 2}, {["name"] = "wool:blue", ["y"] = 2, ["z"] = 6, ["x"] = 2}, {["name"] = "wool:blue", ["y"] = 2, ["z"] = 7, ["x"] = 2}, {["name"] = "wool:blue", ["y"] = 2, ["z"] = 8, ["x"] = 2}, {["name"] = "wool:green", ["y"] = 2, ["z"] = 11, ["x"] = 2}, {["name"] = "wool:white", ["y"] = 2, ["z"] = 12, ["x"] = 2}, {["name"] = "wool:green", ["y"] = 2, ["z"] = 13, ["x"] = 2}, {["name"] = "wool:red", ["y"] = 3, ["z"] = 3, ["x"] = 2}, {["name"] = "wool:white", ["y"] = 3, ["z"] = 4, ["x"] = 2}, {["name"] = "wool:red", ["y"] = 3, ["z"] = 5, ["x"] = 2}, {["name"] = "wool:orange", ["y"] = 3, ["z"] = 6, ["x"] = 2}, {["name"] = "wool:white", ["y"] = 3, ["z"] = 7, ["x"] = 2}, {["name"] = "wool:orange", ["y"] = 3, ["z"] = 8, ["x"] = 2}, {["name"] = "wool:green", ["y"] = 3, ["z"] = 10, ["x"] = 2}, {["name"] = "wool:white", ["y"] = 3, ["z"] = 11, ["x"] = 2}, {["name"] = "wool:green", ["y"] = 3, ["z"] = 12, ["x"] = 2}, {["name"] = "wool:red", ["y"] = 4, ["z"] = 3, ["x"] = 2}, {["name"] = "wool:white", ["y"] = 4, ["z"] = 4, ["x"] = 2}, {["name"] = "wool:red", ["y"] = 4, ["z"] = 5, ["x"] = 2}, {["name"] = "wool:orange", ["y"] = 4, ["z"] = 6, ["x"] = 2}, {["name"] = "wool:white", ["y"] = 4, ["z"] = 7, ["x"] = 2}, {["name"] = "wool:orange", ["y"] = 4, ["z"] = 8, ["x"] = 2}, {["name"] = "wool:green", ["y"] = 4, ["z"] = 9, ["x"] = 2}, {["name"] = "wool:white", ["y"] = 4, ["z"] = 10, ["x"] = 2}, {["name"] = "wool:green", ["y"] = 4, ["z"] = 11, ["x"] = 2}, {["name"] = "wool:red", ["y"] = 5, ["z"] = 3, ["x"] = 2}, {["name"] = "wool:white", ["y"] = 5, ["z"] = 4, ["x"] = 2}, {["name"] = "wool:red", ["y"] = 5, ["z"] = 5, ["x"] = 2}, {["name"] = "wool:orange", ["y"] = 5, ["z"] = 6, ["x"] = 2}, {["name"] = "wool:white", ["y"] = 5, ["z"] = 7, ["x"] = 2}, {["name"] = "wool:orange", ["y"] = 5, ["z"] = 8, ["x"] = 2}, {["name"] = "wool:green", ["y"] = 5, ["z"] = 9, ["x"] = 2}, {["name"] = "wool:green", ["y"] = 5, ["z"] = 10, ["x"] = 2}, {["name"] = "wool:red", ["y"] = 6, ["z"] = 3, ["x"] = 2}, {["name"] = "wool:white", ["y"] = 6, ["z"] = 4, ["x"] = 2}, {["name"] = "wool:red", ["y"] = 6, ["z"] = 5, ["x"] = 2}, {["name"] = "wool:orange", ["y"] = 6, ["z"] = 6, ["x"] = 2}, {["name"] = "wool:white", ["y"] = 6, ["z"] = 7, ["x"] = 2}, {["name"] = "wool:orange", ["y"] = 6, ["z"] = 8, ["x"] = 2}, {["name"] = "wool:red", ["y"] = 7, ["z"] = 3, ["x"] = 2}, {["name"] = "wool:white", ["y"] = 7, ["z"] = 4, ["x"] = 2}, {["name"] = "wool:red", ["y"] = 7, ["z"] = 5, ["x"] = 2}, {["name"] = "wool:orange", ["y"] = 7, ["z"] = 6, ["x"] = 2}, {["name"] = "wool:white", ["y"] = 7, ["z"] = 7, ["x"] = 2}, {["name"] = "wool:orange", ["y"] = 7, ["z"] = 8, ["x"] = 2}, {["name"] = "wool:red", ["y"] = 8, ["z"] = 3, ["x"] = 2}, {["name"] = "wool:white", ["y"] = 8, ["z"] = 4, ["x"] = 2}, {["name"] = "wool:red", ["y"] = 8, ["z"] = 5, ["x"] = 2}, {["name"] = "wool:orange", ["y"] = 8, ["z"] = 6, ["x"] = 2}, {["name"] = "wool:white", ["y"] = 8, ["z"] = 7, ["x"] = 2}, {["name"] = "wool:orange", ["y"] = 8, ["z"] = 8, ["x"] = 2}, {["name"] = "default:wood", ["y"] = 10, ["z"] = 0, ["x"] = 2}, {["name"] = "default:wood", ["y"] = 10, ["z"] = 1, ["x"] = 2}, {["name"] = "default:wood", ["y"] = 10, ["z"] = 2, ["x"] = 2}, {["name"] = "default:wood", ["y"] = 10, ["z"] = 3, ["x"] = 2}, {["name"] = "default:wood", ["y"] = 10, ["z"] = 4, ["x"] = 2}, {["name"] = "default:wood", ["y"] = 10, ["z"] = 5, ["x"] = 2}, {["name"] = "default:wood", ["y"] = 10, ["z"] = 6, ["x"] = 2}, {["name"] = "default:wood", ["y"] = 10, ["z"] = 7, ["x"] = 2}, {["name"] = "default:wood", ["y"] = 10, ["z"] = 8, ["x"] = 2}, {["name"] = "default:wood", ["y"] = 10, ["z"] = 9, ["x"] = 2}, {["name"] = "default:wood", ["y"] = 10, ["z"] = 10, ["x"] = 2}, {["name"] = "default:wood", ["y"] = 10, ["z"] = 11, ["x"] = 2}, {["name"] = "default:wood", ["y"] = 10, ["z"] = 12, ["x"] = 2}, {["name"] = "default:wood", ["y"] = 10, ["z"] = 13, ["x"] = 2}, {["name"] = "default:wood", ["y"] = 10, ["z"] = 14, ["x"] = 2}, {["name"] = "default:wood", ["y"] = 10, ["z"] = 15, ["x"] = 2}, {["name"] = "default:wood", ["y"] = 10, ["z"] = 16, ["x"] = 2}, {["name"] = "default:silver_sandstone_block", ["y"] = 11, ["z"] = 2, ["x"] = 2}, {["name"] = "default:silver_sandstone_block", ["y"] = 11, ["z"] = 3, ["x"] = 2}, {["name"] = "wool:dark_green", ["y"] = 11, ["z"] = 14, ["x"] = 2}, {["name"] = "wool:dark_green", ["y"] = 11, ["z"] = 15, ["x"] = 2}, {["name"] = "wool:yellow", ["y"] = 12, ["z"] = 14, ["x"] = 2}, {["name"] = "wool:yellow", ["y"] = 12, ["z"] = 15, ["x"] = 2}, {["name"] = "wool:yellow", ["y"] = 13, ["z"] = 14, ["x"] = 2}, {["name"] = "wool:yellow", ["y"] = 13, ["z"] = 15, ["x"] = 2}, {["name"] = "wool:yellow", ["y"] = 14, ["z"] = 14, ["x"] = 2}, {["name"] = "wool:yellow", ["y"] = 14, ["z"] = 15, ["x"] = 2}, {["name"] = "wool:yellow", ["y"] = 15, ["z"] = 14, ["x"] = 2}, {["name"] = "wool:yellow", ["y"] = 15, ["z"] = 15, ["x"] = 2}, {["name"] = "wool:dark_green", ["y"] = 16, ["z"] = 14, ["x"] = 2}, {["name"] = "wool:dark_green", ["y"] = 16, ["z"] = 15, ["x"] = 2}, {["name"] = "wool:blue", ["y"] = 0, ["z"] = 3, ["x"] = 3}, {["name"] = "wool:blue", ["y"] = 0, ["z"] = 4, ["x"] = 3}, {["name"] = "wool:blue", ["y"] = 0, ["z"] = 5, ["x"] = 3}, {["name"] = "wool:blue", ["y"] = 0, ["z"] = 6, ["x"] = 3}, {["name"] = "wool:blue", ["y"] = 0, ["z"] = 7, ["x"] = 3}, {["name"] = "wool:blue", ["y"] = 0, ["z"] = 8, ["x"] = 3}, {["name"] = "wool:green", ["y"] = 0, ["z"] = 13, ["x"] = 3}, {["name"] = "wool:white", ["y"] = 0, ["z"] = 14, ["x"] = 3}, {["name"] = "wool:green", ["y"] = 0, ["z"] = 15, ["x"] = 3}, {["name"] = "wool:white", ["y"] = 1, ["z"] = 3, ["x"] = 3}, {["name"] = "wool:white", ["y"] = 1, ["z"] = 4, ["x"] = 3}, {["name"] = "wool:white", ["y"] = 1, ["z"] = 5, ["x"] = 3}, {["name"] = "wool:white", ["y"] = 1, ["z"] = 6, ["x"] = 3}, {["name"] = "wool:white", ["y"] = 1, ["z"] = 7, ["x"] = 3}, {["name"] = "wool:white", ["y"] = 1, ["z"] = 8, ["x"] = 3}, {["name"] = "wool:green", ["y"] = 1, ["z"] = 12, ["x"] = 3}, {["name"] = "wool:white", ["y"] = 1, ["z"] = 13, ["x"] = 3}, {["name"] = "wool:green", ["y"] = 1, ["z"] = 14, ["x"] = 3}, {["name"] = "wool:blue", ["y"] = 2, ["z"] = 3, ["x"] = 3}, {["name"] = "wool:blue", ["y"] = 2, ["z"] = 4, ["x"] = 3}, {["name"] = "wool:blue", ["y"] = 2, ["z"] = 5, ["x"] = 3}, {["name"] = "wool:blue", ["y"] = 2, ["z"] = 6, ["x"] = 3}, {["name"] = "wool:blue", ["y"] = 2, ["z"] = 7, ["x"] = 3}, {["name"] = "wool:blue", ["y"] = 2, ["z"] = 8, ["x"] = 3}, {["name"] = "wool:green", ["y"] = 2, ["z"] = 11, ["x"] = 3}, {["name"] = "wool:white", ["y"] = 2, ["z"] = 12, ["x"] = 3}, {["name"] = "wool:green", ["y"] = 2, ["z"] = 13, ["x"] = 3}, {["name"] = "wool:red", ["y"] = 3, ["z"] = 3, ["x"] = 3}, {["name"] = "wool:white", ["y"] = 3, ["z"] = 4, ["x"] = 3}, {["name"] = "wool:red", ["y"] = 3, ["z"] = 5, ["x"] = 3}, {["name"] = "wool:orange", ["y"] = 3, ["z"] = 6, ["x"] = 3}, {["name"] = "wool:white", ["y"] = 3, ["z"] = 7, ["x"] = 3}, {["name"] = "wool:orange", ["y"] = 3, ["z"] = 8, ["x"] = 3}, {["name"] = "wool:green", ["y"] = 3, ["z"] = 10, ["x"] = 3}, {["name"] = "wool:white", ["y"] = 3, ["z"] = 11, ["x"] = 3}, {["name"] = "wool:green", ["y"] = 3, ["z"] = 12, ["x"] = 3}, {["name"] = "wool:red", ["y"] = 4, ["z"] = 3, ["x"] = 3}, {["name"] = "wool:white", ["y"] = 4, ["z"] = 4, ["x"] = 3}, {["name"] = "wool:red", ["y"] = 4, ["z"] = 5, ["x"] = 3}, {["name"] = "wool:orange", ["y"] = 4, ["z"] = 6, ["x"] = 3}, {["name"] = "wool:white", ["y"] = 4, ["z"] = 7, ["x"] = 3}, {["name"] = "wool:orange", ["y"] = 4, ["z"] = 8, ["x"] = 3}, {["name"] = "wool:green", ["y"] = 4, ["z"] = 9, ["x"] = 3}, {["name"] = "wool:white", ["y"] = 4, ["z"] = 10, ["x"] = 3}, {["name"] = "wool:green", ["y"] = 4, ["z"] = 11, ["x"] = 3}, {["name"] = "wool:red", ["y"] = 5, ["z"] = 3, ["x"] = 3}, {["name"] = "wool:white", ["y"] = 5, ["z"] = 4, ["x"] = 3}, {["name"] = "wool:red", ["y"] = 5, ["z"] = 5, ["x"] = 3}, {["name"] = "wool:orange", ["y"] = 5, ["z"] = 6, ["x"] = 3}, {["name"] = "wool:white", ["y"] = 5, ["z"] = 7, ["x"] = 3}, {["name"] = "wool:orange", ["y"] = 5, ["z"] = 8, ["x"] = 3}, {["name"] = "wool:green", ["y"] = 5, ["z"] = 9, ["x"] = 3}, {["name"] = "wool:green", ["y"] = 5, ["z"] = 10, ["x"] = 3}, {["name"] = "wool:red", ["y"] = 6, ["z"] = 3, ["x"] = 3}, {["name"] = "wool:white", ["y"] = 6, ["z"] = 4, ["x"] = 3}, {["name"] = "wool:red", ["y"] = 6, ["z"] = 5, ["x"] = 3}, {["name"] = "wool:orange", ["y"] = 6, ["z"] = 6, ["x"] = 3}, {["name"] = "wool:white", ["y"] = 6, ["z"] = 7, ["x"] = 3}, {["name"] = "wool:orange", ["y"] = 6, ["z"] = 8, ["x"] = 3}, {["name"] = "wool:red", ["y"] = 7, ["z"] = 3, ["x"] = 3}, {["name"] = "wool:white", ["y"] = 7, ["z"] = 4, ["x"] = 3}, {["name"] = "wool:red", ["y"] = 7, ["z"] = 5, ["x"] = 3}, {["name"] = "wool:orange", ["y"] = 7, ["z"] = 6, ["x"] = 3}, {["name"] = "wool:white", ["y"] = 7, ["z"] = 7, ["x"] = 3}, {["name"] = "wool:orange", ["y"] = 7, ["z"] = 8, ["x"] = 3}, {["name"] = "wool:red", ["y"] = 8, ["z"] = 3, ["x"] = 3}, {["name"] = "wool:white", ["y"] = 8, ["z"] = 4, ["x"] = 3}, {["name"] = "wool:red", ["y"] = 8, ["z"] = 5, ["x"] = 3}, {["name"] = "wool:orange", ["y"] = 8, ["z"] = 6, ["x"] = 3}, {["name"] = "wool:white", ["y"] = 8, ["z"] = 7, ["x"] = 3}, {["name"] = "wool:orange", ["y"] = 8, ["z"] = 8, ["x"] = 3}, {["name"] = "default:wood", ["y"] = 10, ["z"] = 0, ["x"] = 3}, {["name"] = "default:wood", ["y"] = 10, ["z"] = 1, ["x"] = 3}, {["name"] = "default:wood", ["y"] = 10, ["z"] = 2, ["x"] = 3}, {["name"] = "default:wood", ["y"] = 10, ["z"] = 3, ["x"] = 3}, {["name"] = "default:wood", ["y"] = 10, ["z"] = 4, ["x"] = 3}, {["name"] = "default:wood", ["y"] = 10, ["z"] = 5, ["x"] = 3}, {["name"] = "default:wood", ["y"] = 10, ["z"] = 6, ["x"] = 3}, {["name"] = "default:wood", ["y"] = 10, ["z"] = 7, ["x"] = 3}, {["name"] = "default:wood", ["y"] = 10, ["z"] = 8, ["x"] = 3}, {["name"] = "default:wood", ["y"] = 10, ["z"] = 9, ["x"] = 3}, {["name"] = "default:wood", ["y"] = 10, ["z"] = 10, ["x"] = 3}, {["name"] = "default:wood", ["y"] = 10, ["z"] = 11, ["x"] = 3}, {["name"] = "default:wood", ["y"] = 10, ["z"] = 12, ["x"] = 3}, {["name"] = "default:wood", ["y"] = 10, ["z"] = 13, ["x"] = 3}, {["name"] = "default:wood", ["y"] = 10, ["z"] = 14, ["x"] = 3}, {["name"] = "default:wood", ["y"] = 10, ["z"] = 15, ["x"] = 3}, {["name"] = "default:wood", ["y"] = 10, ["z"] = 16, ["x"] = 3}, {["name"] = "default:silver_sandstone_block", ["y"] = 11, ["z"] = 1, ["x"] = 3}, {["name"] = "default:silver_sandstone_block", ["y"] = 11, ["z"] = 4, ["x"] = 3}, {["name"] = "default:silver_sandstone_block", ["y"] = 11, ["z"] = 5, ["x"] = 3}, {["name"] = "default:silver_sandstone_block", ["y"] = 11, ["z"] = 6, ["x"] = 3}, {["name"] = "default:silver_sandstone_block", ["y"] = 11, ["z"] = 7, ["x"] = 3}, {["name"] = "default:silver_sandstone_block", ["y"] = 11, ["z"] = 8, ["x"] = 3}, {["name"] = "default:silver_sandstone_block", ["y"] = 11, ["z"] = 9, ["x"] = 3}, {["name"] = "default:silver_sandstone_block", ["y"] = 11, ["z"] = 10, ["x"] = 3}, {["name"] = "wool:blue", ["y"] = 0, ["z"] = 3, ["x"] = 4}, {["name"] = "wool:blue", ["y"] = 0, ["z"] = 4, ["x"] = 4}, {["name"] = "wool:blue", ["y"] = 0, ["z"] = 5, ["x"] = 4}, {["name"] = "wool:blue", ["y"] = 0, ["z"] = 6, ["x"] = 4}, {["name"] = "wool:blue", ["y"] = 0, ["z"] = 7, ["x"] = 4}, {["name"] = "wool:blue", ["y"] = 0, ["z"] = 8, ["x"] = 4}, {["name"] = "wool:green", ["y"] = 0, ["z"] = 13, ["x"] = 4}, {["name"] = "wool:white", ["y"] = 0, ["z"] = 14, ["x"] = 4}, {["name"] = "wool:green", ["y"] = 0, ["z"] = 15, ["x"] = 4}, {["name"] = "wool:white", ["y"] = 1, ["z"] = 3, ["x"] = 4}, {["name"] = "wool:white", ["y"] = 1, ["z"] = 4, ["x"] = 4}, {["name"] = "wool:white", ["y"] = 1, ["z"] = 5, ["x"] = 4}, {["name"] = "wool:white", ["y"] = 1, ["z"] = 6, ["x"] = 4}, {["name"] = "wool:white", ["y"] = 1, ["z"] = 7, ["x"] = 4}, {["name"] = "wool:white", ["y"] = 1, ["z"] = 8, ["x"] = 4}, {["name"] = "wool:green", ["y"] = 1, ["z"] = 12, ["x"] = 4}, {["name"] = "wool:white", ["y"] = 1, ["z"] = 13, ["x"] = 4}, {["name"] = "wool:green", ["y"] = 1, ["z"] = 14, ["x"] = 4}, {["name"] = "wool:blue", ["y"] = 2, ["z"] = 3, ["x"] = 4}, {["name"] = "wool:blue", ["y"] = 2, ["z"] = 4, ["x"] = 4}, {["name"] = "wool:blue", ["y"] = 2, ["z"] = 5, ["x"] = 4}, {["name"] = "wool:blue", ["y"] = 2, ["z"] = 6, ["x"] = 4}, {["name"] = "wool:blue", ["y"] = 2, ["z"] = 7, ["x"] = 4}, {["name"] = "wool:blue", ["y"] = 2, ["z"] = 8, ["x"] = 4}, {["name"] = "wool:green", ["y"] = 2, ["z"] = 11, ["x"] = 4}, {["name"] = "wool:white", ["y"] = 2, ["z"] = 12, ["x"] = 4}, {["name"] = "wool:green", ["y"] = 2, ["z"] = 13, ["x"] = 4}, {["name"] = "wool:red", ["y"] = 3, ["z"] = 3, ["x"] = 4}, {["name"] = "wool:white", ["y"] = 3, ["z"] = 4, ["x"] = 4}, {["name"] = "wool:red", ["y"] = 3, ["z"] = 5, ["x"] = 4}, {["name"] = "wool:orange", ["y"] = 3, ["z"] = 6, ["x"] = 4}, {["name"] = "wool:orange", ["y"] = 3, ["z"] = 7, ["x"] = 4}, {["name"] = "wool:orange", ["y"] = 3, ["z"] = 8, ["x"] = 4}, {["name"] = "wool:green", ["y"] = 3, ["z"] = 10, ["x"] = 4}, {["name"] = "wool:white", ["y"] = 3, ["z"] = 11, ["x"] = 4}, {["name"] = "wool:green", ["y"] = 3, ["z"] = 12, ["x"] = 4}, {["name"] = "wool:red", ["y"] = 4, ["z"] = 3, ["x"] = 4}, {["name"] = "wool:white", ["y"] = 4, ["z"] = 4, ["x"] = 4}, {["name"] = "wool:red", ["y"] = 4, ["z"] = 5, ["x"] = 4}, {["name"] = "wool:orange", ["y"] = 4, ["z"] = 6, ["x"] = 4}, {["name"] = "wool:orange", ["y"] = 4, ["z"] = 7, ["x"] = 4}, {["name"] = "wool:orange", ["y"] = 4, ["z"] = 8, ["x"] = 4}, {["name"] = "wool:green", ["y"] = 4, ["z"] = 9, ["x"] = 4}, {["name"] = "wool:white", ["y"] = 4, ["z"] = 10, ["x"] = 4}, {["name"] = "wool:green", ["y"] = 4, ["z"] = 11, ["x"] = 4}, {["name"] = "wool:red", ["y"] = 5, ["z"] = 3, ["x"] = 4}, {["name"] = "wool:white", ["y"] = 5, ["z"] = 4, ["x"] = 4}, {["name"] = "wool:red", ["y"] = 5, ["z"] = 5, ["x"] = 4}, {["name"] = "wool:orange", ["y"] = 5, ["z"] = 6, ["x"] = 4}, {["name"] = "wool:orange", ["y"] = 5, ["z"] = 7, ["x"] = 4}, {["name"] = "wool:orange", ["y"] = 5, ["z"] = 8, ["x"] = 4}, {["name"] = "wool:green", ["y"] = 5, ["z"] = 9, ["x"] = 4}, {["name"] = "wool:green", ["y"] = 5, ["z"] = 10, ["x"] = 4}, {["name"] = "wool:red", ["y"] = 6, ["z"] = 3, ["x"] = 4}, {["name"] = "wool:white", ["y"] = 6, ["z"] = 4, ["x"] = 4}, {["name"] = "wool:red", ["y"] = 6, ["z"] = 5, ["x"] = 4}, {["name"] = "wool:orange", ["y"] = 6, ["z"] = 6, ["x"] = 4}, {["name"] = "wool:orange", ["y"] = 6, ["z"] = 7, ["x"] = 4}, {["name"] = "wool:orange", ["y"] = 6, ["z"] = 8, ["x"] = 4}, {["name"] = "wool:red", ["y"] = 7, ["z"] = 3, ["x"] = 4}, {["name"] = "wool:white", ["y"] = 7, ["z"] = 4, ["x"] = 4}, {["name"] = "wool:red", ["y"] = 7, ["z"] = 5, ["x"] = 4}, {["name"] = "wool:orange", ["y"] = 7, ["z"] = 6, ["x"] = 4}, {["name"] = "wool:orange", ["y"] = 7, ["z"] = 7, ["x"] = 4}, {["name"] = "wool:orange", ["y"] = 7, ["z"] = 8, ["x"] = 4}, {["name"] = "wool:red", ["y"] = 8, ["z"] = 3, ["x"] = 4}, {["name"] = "wool:white", ["y"] = 8, ["z"] = 4, ["x"] = 4}, {["name"] = "wool:red", ["y"] = 8, ["z"] = 5, ["x"] = 4}, {["name"] = "wool:orange", ["y"] = 8, ["z"] = 6, ["x"] = 4}, {["name"] = "wool:orange", ["y"] = 8, ["z"] = 7, ["x"] = 4}, {["name"] = "wool:orange", ["y"] = 8, ["z"] = 8, ["x"] = 4}, {["name"] = "default:wood", ["y"] = 10, ["z"] = 0, ["x"] = 4}, {["name"] = "default:wood", ["y"] = 10, ["z"] = 1, ["x"] = 4}, {["name"] = "default:wood", ["y"] = 10, ["z"] = 2, ["x"] = 4}, {["name"] = "default:wood", ["y"] = 10, ["z"] = 3, ["x"] = 4}, {["name"] = "default:wood", ["y"] = 10, ["z"] = 4, ["x"] = 4}, {["name"] = "default:wood", ["y"] = 10, ["z"] = 5, ["x"] = 4}, {["name"] = "default:wood", ["y"] = 10, ["z"] = 6, ["x"] = 4}, {["name"] = "default:wood", ["y"] = 10, ["z"] = 7, ["x"] = 4}, {["name"] = "default:wood", ["y"] = 10, ["z"] = 8, ["x"] = 4}, {["name"] = "default:wood", ["y"] = 10, ["z"] = 9, ["x"] = 4}, {["name"] = "default:wood", ["y"] = 10, ["z"] = 10, ["x"] = 4}, {["name"] = "default:wood", ["y"] = 10, ["z"] = 11, ["x"] = 4}, {["name"] = "default:wood", ["y"] = 10, ["z"] = 12, ["x"] = 4}, {["name"] = "default:wood", ["y"] = 10, ["z"] = 13, ["x"] = 4}, {["name"] = "default:wood", ["y"] = 10, ["z"] = 14, ["x"] = 4}, {["name"] = "default:wood", ["y"] = 10, ["z"] = 15, ["x"] = 4}, {["name"] = "default:wood", ["y"] = 10, ["z"] = 16, ["x"] = 4}, {["name"] = "default:silver_sandstone_block", ["y"] = 11, ["z"] = 2, ["x"] = 4}, {["name"] = "default:silver_sandstone_block", ["y"] = 11, ["z"] = 3, ["x"] = 4}, {["name"] = "default:wood", ["y"] = 10, ["z"] = 0, ["x"] = 5}, {["name"] = "default:wood", ["y"] = 10, ["z"] = 1, ["x"] = 5}, {["name"] = "default:wood", ["y"] = 10, ["z"] = 2, ["x"] = 5}, {["name"] = "default:wood", ["y"] = 10, ["z"] = 3, ["x"] = 5}, {["name"] = "default:wood", ["y"] = 10, ["z"] = 4, ["x"] = 5}, {["name"] = "default:wood", ["y"] = 10, ["z"] = 5, ["x"] = 5}, {["name"] = "default:wood", ["y"] = 10, ["z"] = 6, ["x"] = 5}, {["name"] = "default:wood", ["y"] = 10, ["z"] = 7, ["x"] = 5}, {["name"] = "default:wood", ["y"] = 10, ["z"] = 8, ["x"] = 5}, {["name"] = "default:wood", ["y"] = 10, ["z"] = 9, ["x"] = 5}, {["name"] = "default:wood", ["y"] = 10, ["z"] = 10, ["x"] = 5}, {["name"] = "default:wood", ["y"] = 10, ["z"] = 11, ["x"] = 5}, {["name"] = "default:wood", ["y"] = 10, ["z"] = 12, ["x"] = 5}, {["name"] = "default:wood", ["y"] = 10, ["z"] = 13, ["x"] = 5}, {["name"] = "default:wood", ["y"] = 10, ["z"] = 14, ["x"] = 5}, {["name"] = "default:wood", ["y"] = 10, ["z"] = 15, ["x"] = 5}, {["name"] = "default:wood", ["y"] = 10, ["z"] = 16, ["x"] = 5}, {["name"] = "wool:red", ["y"] = 11, ["z"] = 2, ["x"] = 5}, {["name"] = "wool:red", ["y"] = 11, ["z"] = 3, ["x"] = 5}, {["name"] = "wool:red", ["y"] = 11, ["z"] = 4, ["x"] = 5}, {["name"] = "wool:red", ["y"] = 11, ["z"] = 5, ["x"] = 5}, {["name"] = "wool:red", ["y"] = 11, ["z"] = 6, ["x"] = 5}, {["name"] = "wool:red", ["y"] = 11, ["z"] = 7, ["x"] = 5}, {["name"] = "wool:red", ["y"] = 11, ["z"] = 8, ["x"] = 5}, {["name"] = "wool:red", ["y"] = 11, ["z"] = 9, ["x"] = 5}, {["name"] = "wool:red", ["y"] = 11, ["z"] = 10, ["x"] = 5}, {["name"] = "wool:red", ["y"] = 11, ["z"] = 11, ["x"] = 5}, {["name"] = "wool:red", ["y"] = 11, ["z"] = 12, ["x"] = 5}, {["name"] = "default:wood", ["y"] = 10, ["z"] = 0, ["x"] = 6}, {["name"] = "default:wood", ["y"] = 10, ["z"] = 1, ["x"] = 6}, {["name"] = "default:wood", ["y"] = 10, ["z"] = 2, ["x"] = 6}, {["name"] = "default:wood", ["y"] = 10, ["z"] = 3, ["x"] = 6}, {["name"] = "default:wood", ["y"] = 10, ["z"] = 4, ["x"] = 6}, {["name"] = "default:wood", ["y"] = 10, ["z"] = 5, ["x"] = 6}, {["name"] = "default:wood", ["y"] = 10, ["z"] = 6, ["x"] = 6}, {["name"] = "default:wood", ["y"] = 10, ["z"] = 7, ["x"] = 6}, {["name"] = "default:wood", ["y"] = 10, ["z"] = 8, ["x"] = 6}, {["name"] = "default:wood", ["y"] = 10, ["z"] = 9, ["x"] = 6}, {["name"] = "default:wood", ["y"] = 10, ["z"] = 10, ["x"] = 6}, {["name"] = "default:wood", ["y"] = 10, ["z"] = 11, ["x"] = 6}, {["name"] = "default:wood", ["y"] = 10, ["z"] = 12, ["x"] = 6}, {["name"] = "default:wood", ["y"] = 10, ["z"] = 13, ["x"] = 6}, {["name"] = "default:wood", ["y"] = 10, ["z"] = 14, ["x"] = 6}, {["name"] = "default:wood", ["y"] = 10, ["z"] = 15, ["x"] = 6}, {["name"] = "default:wood", ["y"] = 10, ["z"] = 16, ["x"] = 6}, {["name"] = "wool:red", ["y"] = 11, ["z"] = 2, ["x"] = 6}, {["name"] = "wool:white", ["y"] = 11, ["z"] = 3, ["x"] = 6}, {["name"] = "wool:white", ["y"] = 11, ["z"] = 4, ["x"] = 6}, {["name"] = "wool:white", ["y"] = 11, ["z"] = 5, ["x"] = 6}, {["name"] = "wool:white", ["y"] = 11, ["z"] = 6, ["x"] = 6}, {["name"] = "wool:white", ["y"] = 11, ["z"] = 7, ["x"] = 6}, {["name"] = "wool:white", ["y"] = 11, ["z"] = 8, ["x"] = 6}, {["name"] = "wool:white", ["y"] = 11, ["z"] = 9, ["x"] = 6}, {["name"] = "wool:white", ["y"] = 11, ["z"] = 10, ["x"] = 6}, {["name"] = "wool:white", ["y"] = 11, ["z"] = 11, ["x"] = 6}, {["name"] = "wool:red", ["y"] = 11, ["z"] = 12, ["x"] = 6}, {["name"] = "stairs:slab_sandstone", ["y"] = 12, ["z"] = 3, ["param1"] = 14, ["x"] = 6}, {["name"] = "stairs:slab_sandstone", ["y"] = 12, ["z"] = 4, ["param1"] = 14, ["x"] = 6}, {["name"] = "stairs:slab_sandstone", ["y"] = 12, ["z"] = 5, ["param1"] = 14, ["x"] = 6}, {["name"] = "stairs:slab_sandstone", ["y"] = 12, ["z"] = 6, ["param1"] = 14, ["x"] = 6}, {["name"] = "stairs:slab_sandstone", ["y"] = 12, ["z"] = 7, ["param1"] = 14, ["x"] = 6}, {["name"] = "stairs:slab_sandstone", ["y"] = 12, ["z"] = 8, ["param1"] = 14, ["x"] = 6}, {["name"] = "stairs:slab_sandstone", ["y"] = 12, ["z"] = 9, ["param1"] = 14, ["x"] = 6}, {["name"] = "stairs:slab_sandstone", ["y"] = 12, ["z"] = 10, ["param1"] = 14, ["x"] = 6}, {["name"] = "stairs:slab_sandstone", ["y"] = 12, ["z"] = 11, ["param1"] = 14, ["x"] = 6}, {["name"] = "default:wood", ["y"] = 10, ["z"] = 0, ["x"] = 7}, {["name"] = "default:wood", ["y"] = 10, ["z"] = 1, ["x"] = 7}, {["name"] = "default:wood", ["y"] = 10, ["z"] = 2, ["x"] = 7}, {["name"] = "default:wood", ["y"] = 10, ["z"] = 3, ["x"] = 7}, {["name"] = "default:wood", ["y"] = 10, ["z"] = 4, ["x"] = 7}, {["name"] = "default:wood", ["y"] = 10, ["z"] = 5, ["x"] = 7}, {["name"] = "default:wood", ["y"] = 10, ["z"] = 6, ["x"] = 7}, {["name"] = "default:wood", ["y"] = 10, ["z"] = 7, ["x"] = 7}, {["name"] = "default:wood", ["y"] = 10, ["z"] = 8, ["x"] = 7}, {["name"] = "default:wood", ["y"] = 10, ["z"] = 9, ["x"] = 7}, {["name"] = "default:wood", ["y"] = 10, ["z"] = 10, ["x"] = 7}, {["name"] = "default:wood", ["y"] = 10, ["z"] = 11, ["x"] = 7}, {["name"] = "default:wood", ["y"] = 10, ["z"] = 12, ["x"] = 7}, {["name"] = "default:wood", ["y"] = 10, ["z"] = 13, ["x"] = 7}, {["name"] = "default:wood", ["y"] = 10, ["z"] = 14, ["x"] = 7}, {["name"] = "default:wood", ["y"] = 10, ["z"] = 15, ["x"] = 7}, {["name"] = "default:wood", ["y"] = 10, ["z"] = 16, ["x"] = 7}, {["name"] = "wool:red", ["y"] = 11, ["z"] = 2, ["x"] = 7}, {["name"] = "wool:white", ["y"] = 11, ["z"] = 3, ["x"] = 7}, {["name"] = "wool:white", ["y"] = 11, ["z"] = 4, ["x"] = 7}, {["name"] = "wool:white", ["y"] = 11, ["z"] = 5, ["x"] = 7}, {["name"] = "wool:white", ["y"] = 11, ["z"] = 6, ["x"] = 7}, {["name"] = "wool:white", ["y"] = 11, ["z"] = 7, ["x"] = 7}, {["name"] = "wool:white", ["y"] = 11, ["z"] = 8, ["x"] = 7}, {["name"] = "wool:white", ["y"] = 11, ["z"] = 9, ["x"] = 7}, {["name"] = "wool:white", ["y"] = 11, ["z"] = 10, ["x"] = 7}, {["name"] = "wool:white", ["y"] = 11, ["z"] = 11, ["x"] = 7}, {["name"] = "wool:red", ["y"] = 11, ["z"] = 12, ["x"] = 7}, {["name"] = "stairs:slab_sandstone", ["y"] = 12, ["z"] = 3, ["param1"] = 14, ["x"] = 7}, {["name"] = "stairs:slab_sandstone", ["y"] = 12, ["z"] = 4, ["param1"] = 14, ["x"] = 7}, {["name"] = "stairs:slab_sandstone", ["y"] = 12, ["z"] = 5, ["param1"] = 14, ["x"] = 7}, {["name"] = "stairs:slab_sandstone", ["y"] = 12, ["z"] = 6, ["param1"] = 14, ["x"] = 7}, {["name"] = "stairs:slab_sandstone", ["y"] = 12, ["z"] = 7, ["param1"] = 14, ["x"] = 7}, {["name"] = "stairs:slab_sandstone", ["y"] = 12, ["z"] = 8, ["param1"] = 14, ["x"] = 7}, {["name"] = "stairs:slab_sandstone", ["y"] = 12, ["z"] = 9, ["param1"] = 14, ["x"] = 7}, {["name"] = "stairs:slab_sandstone", ["y"] = 12, ["z"] = 10, ["param1"] = 14, ["x"] = 7}, {["name"] = "stairs:slab_sandstone", ["y"] = 12, ["z"] = 11, ["param1"] = 14, ["x"] = 7}, {["name"] = "default:wood", ["y"] = 10, ["z"] = 0, ["x"] = 8}, {["name"] = "default:wood", ["y"] = 10, ["z"] = 1, ["x"] = 8}, {["name"] = "default:wood", ["y"] = 10, ["z"] = 2, ["x"] = 8}, {["name"] = "default:wood", ["y"] = 10, ["z"] = 3, ["x"] = 8}, {["name"] = "default:wood", ["y"] = 10, ["z"] = 4, ["x"] = 8}, {["name"] = "default:wood", ["y"] = 10, ["z"] = 5, ["x"] = 8}, {["name"] = "default:wood", ["y"] = 10, ["z"] = 6, ["x"] = 8}, {["name"] = "default:wood", ["y"] = 10, ["z"] = 7, ["x"] = 8}, {["name"] = "default:wood", ["y"] = 10, ["z"] = 8, ["x"] = 8}, {["name"] = "default:wood", ["y"] = 10, ["z"] = 9, ["x"] = 8}, {["name"] = "default:wood", ["y"] = 10, ["z"] = 10, ["x"] = 8}, {["name"] = "default:wood", ["y"] = 10, ["z"] = 11, ["x"] = 8}, {["name"] = "default:wood", ["y"] = 10, ["z"] = 12, ["x"] = 8}, {["name"] = "default:wood", ["y"] = 10, ["z"] = 13, ["x"] = 8}, {["name"] = "default:wood", ["y"] = 10, ["z"] = 14, ["x"] = 8}, {["name"] = "default:wood", ["y"] = 10, ["z"] = 15, ["x"] = 8}, {["name"] = "default:wood", ["y"] = 10, ["z"] = 16, ["x"] = 8}, {["name"] = "wool:red", ["y"] = 11, ["z"] = 2, ["x"] = 8}, {["name"] = "wool:white", ["y"] = 11, ["z"] = 3, ["x"] = 8}, {["name"] = "wool:white", ["y"] = 11, ["z"] = 4, ["x"] = 8}, {["name"] = "wool:white", ["y"] = 11, ["z"] = 5, ["x"] = 8}, {["name"] = "wool:white", ["y"] = 11, ["z"] = 6, ["x"] = 8}, {["name"] = "wool:white", ["y"] = 11, ["z"] = 7, ["x"] = 8}, {["name"] = "wool:white", ["y"] = 11, ["z"] = 8, ["x"] = 8}, {["name"] = "wool:white", ["y"] = 11, ["z"] = 9, ["x"] = 8}, {["name"] = "wool:white", ["y"] = 11, ["z"] = 10, ["x"] = 8}, {["name"] = "wool:white", ["y"] = 11, ["z"] = 11, ["x"] = 8}, {["name"] = "wool:red", ["y"] = 11, ["z"] = 12, ["x"] = 8}, {["name"] = "stairs:slab_sandstone", ["y"] = 12, ["z"] = 3, ["param1"] = 14, ["x"] = 8}, {["name"] = "stairs:slab_sandstone", ["y"] = 12, ["z"] = 4, ["param1"] = 14, ["x"] = 8}, {["name"] = "stairs:slab_sandstone", ["y"] = 12, ["z"] = 5, ["param1"] = 14, ["x"] = 8}, {["name"] = "stairs:slab_sandstone", ["y"] = 12, ["z"] = 6, ["param1"] = 14, ["x"] = 8}, {["name"] = "stairs:slab_sandstone", ["y"] = 12, ["z"] = 7, ["param1"] = 14, ["x"] = 8}, {["name"] = "stairs:slab_sandstone", ["y"] = 12, ["z"] = 8, ["param1"] = 14, ["x"] = 8}, {["name"] = "stairs:slab_sandstone", ["y"] = 12, ["z"] = 9, ["param1"] = 14, ["param2"] = 1, ["x"] = 8}, {["name"] = "stairs:slab_sandstone", ["y"] = 12, ["z"] = 10, ["param1"] = 14, ["param2"] = 1, ["x"] = 8}, {["name"] = "stairs:slab_sandstone", ["y"] = 12, ["z"] = 11, ["param1"] = 14, ["x"] = 8}, {["name"] = "default:wood", ["y"] = 10, ["z"] = 0, ["x"] = 9}, {["name"] = "default:wood", ["y"] = 10, ["z"] = 1, ["x"] = 9}, {["name"] = "default:wood", ["y"] = 10, ["z"] = 2, ["x"] = 9}, {["name"] = "default:wood", ["y"] = 10, ["z"] = 3, ["x"] = 9}, {["name"] = "default:wood", ["y"] = 10, ["z"] = 4, ["x"] = 9}, {["name"] = "default:wood", ["y"] = 10, ["z"] = 5, ["x"] = 9}, {["name"] = "default:wood", ["y"] = 10, ["z"] = 6, ["x"] = 9}, {["name"] = "default:wood", ["y"] = 10, ["z"] = 7, ["x"] = 9}, {["name"] = "default:wood", ["y"] = 10, ["z"] = 8, ["x"] = 9}, {["name"] = "default:wood", ["y"] = 10, ["z"] = 9, ["x"] = 9}, {["name"] = "default:wood", ["y"] = 10, ["z"] = 10, ["x"] = 9}, {["name"] = "default:wood", ["y"] = 10, ["z"] = 11, ["x"] = 9}, {["name"] = "default:wood", ["y"] = 10, ["z"] = 12, ["x"] = 9}, {["name"] = "default:wood", ["y"] = 10, ["z"] = 13, ["x"] = 9}, {["name"] = "default:wood", ["y"] = 10, ["z"] = 14, ["x"] = 9}, {["name"] = "default:wood", ["y"] = 10, ["z"] = 15, ["x"] = 9}, {["name"] = "default:wood", ["y"] = 10, ["z"] = 16, ["x"] = 9}, {["name"] = "wool:red", ["y"] = 11, ["z"] = 2, ["x"] = 9}, {["name"] = "wool:white", ["y"] = 11, ["z"] = 3, ["x"] = 9}, {["name"] = "wool:white", ["y"] = 11, ["z"] = 4, ["x"] = 9}, {["name"] = "wool:white", ["y"] = 11, ["z"] = 5, ["x"] = 9}, {["name"] = "wool:white", ["y"] = 11, ["z"] = 6, ["x"] = 9}, {["name"] = "wool:white", ["y"] = 11, ["z"] = 7, ["x"] = 9}, {["name"] = "wool:white", ["y"] = 11, ["z"] = 8, ["x"] = 9}, {["name"] = "wool:white", ["y"] = 11, ["z"] = 9, ["x"] = 9}, {["name"] = "wool:white", ["y"] = 11, ["z"] = 10, ["x"] = 9}, {["name"] = "wool:white", ["y"] = 11, ["z"] = 11, ["x"] = 9}, {["name"] = "wool:red", ["y"] = 11, ["z"] = 12, ["x"] = 9}, {["name"] = "stairs:slab_sandstone", ["y"] = 12, ["z"] = 3, ["param1"] = 14, ["x"] = 9}, {["name"] = "stairs:slab_sandstone", ["y"] = 12, ["z"] = 4, ["param1"] = 14, ["x"] = 9}, {["name"] = "stairs:slab_sandstone", ["y"] = 12, ["z"] = 5, ["param1"] = 14, ["param2"] = 1, ["x"] = 9}, {["name"] = "stairs:slab_sandstone", ["y"] = 12, ["z"] = 6, ["param1"] = 14, ["x"] = 9}, {["name"] = "stairs:slab_sandstone", ["y"] = 12, ["z"] = 7, ["param1"] = 14, ["x"] = 9}, {["name"] = "stairs:slab_sandstone", ["y"] = 12, ["z"] = 8, ["param1"] = 14, ["x"] = 9}, {["name"] = "stairs:slab_sandstone", ["y"] = 12, ["z"] = 9, ["param1"] = 14, ["param2"] = 1, ["x"] = 9}, {["name"] = "stairs:slab_sandstone", ["y"] = 12, ["z"] = 10, ["param1"] = 14, ["param2"] = 1, ["x"] = 9}, {["name"] = "stairs:slab_sandstone", ["y"] = 12, ["z"] = 11, ["param1"] = 14, ["x"] = 9}, {["name"] = "default:wood", ["y"] = 10, ["z"] = 0, ["x"] = 10}, {["name"] = "default:wood", ["y"] = 10, ["z"] = 1, ["x"] = 10}, {["name"] = "default:wood", ["y"] = 10, ["z"] = 2, ["x"] = 10}, {["name"] = "default:wood", ["y"] = 10, ["z"] = 3, ["x"] = 10}, {["name"] = "default:wood", ["y"] = 10, ["z"] = 4, ["x"] = 10}, {["name"] = "default:wood", ["y"] = 10, ["z"] = 5, ["x"] = 10}, {["name"] = "default:wood", ["y"] = 10, ["z"] = 6, ["x"] = 10}, {["name"] = "default:wood", ["y"] = 10, ["z"] = 7, ["x"] = 10}, {["name"] = "default:wood", ["y"] = 10, ["z"] = 8, ["x"] = 10}, {["name"] = "default:wood", ["y"] = 10, ["z"] = 9, ["x"] = 10}, {["name"] = "default:wood", ["y"] = 10, ["z"] = 10, ["x"] = 10}, {["name"] = "default:wood", ["y"] = 10, ["z"] = 11, ["x"] = 10}, {["name"] = "default:wood", ["y"] = 10, ["z"] = 12, ["x"] = 10}, {["name"] = "default:wood", ["y"] = 10, ["z"] = 13, ["x"] = 10}, {["name"] = "default:wood", ["y"] = 10, ["z"] = 14, ["x"] = 10}, {["name"] = "default:wood", ["y"] = 10, ["z"] = 15, ["x"] = 10}, {["name"] = "default:wood", ["y"] = 10, ["z"] = 16, ["x"] = 10}, {["name"] = "wool:red", ["y"] = 11, ["z"] = 2, ["x"] = 10}, {["name"] = "wool:red", ["y"] = 11, ["z"] = 3, ["x"] = 10}, {["name"] = "wool:red", ["y"] = 11, ["z"] = 4, ["x"] = 10}, {["name"] = "wool:red", ["y"] = 11, ["z"] = 5, ["x"] = 10}, {["name"] = "wool:red", ["y"] = 11, ["z"] = 6, ["x"] = 10}, {["name"] = "wool:red", ["y"] = 11, ["z"] = 7, ["x"] = 10}, {["name"] = "wool:red", ["y"] = 11, ["z"] = 8, ["x"] = 10}, {["name"] = "wool:red", ["y"] = 11, ["z"] = 9, ["x"] = 10}, {["name"] = "wool:red", ["y"] = 11, ["z"] = 10, ["x"] = 10}, {["name"] = "wool:red", ["y"] = 11, ["z"] = 11, ["x"] = 10}, {["name"] = "wool:red", ["y"] = 11, ["z"] = 12, ["x"] = 10}, {["name"] = "default:wood", ["y"] = 10, ["z"] = 0, ["x"] = 11}, {["name"] = "default:wood", ["y"] = 10, ["z"] = 1, ["x"] = 11}, {["name"] = "default:wood", ["y"] = 10, ["z"] = 2, ["x"] = 11}, {["name"] = "default:wood", ["y"] = 10, ["z"] = 3, ["x"] = 11}, {["name"] = "default:wood", ["y"] = 10, ["z"] = 4, ["x"] = 11}, {["name"] = "default:wood", ["y"] = 10, ["z"] = 5, ["x"] = 11}, {["name"] = "default:wood", ["y"] = 10, ["z"] = 6, ["x"] = 11}, {["name"] = "default:wood", ["y"] = 10, ["z"] = 7, ["x"] = 11}, {["name"] = "default:wood", ["y"] = 10, ["z"] = 8, ["x"] = 11}, {["name"] = "default:wood", ["y"] = 10, ["z"] = 9, ["x"] = 11}, {["name"] = "default:wood", ["y"] = 10, ["z"] = 10, ["x"] = 11}, {["name"] = "default:wood", ["y"] = 10, ["z"] = 11, ["x"] = 11}, {["name"] = "default:wood", ["y"] = 10, ["z"] = 12, ["x"] = 11}, {["name"] = "default:wood", ["y"] = 10, ["z"] = 13, ["x"] = 11}, {["name"] = "default:wood", ["y"] = 10, ["z"] = 14, ["x"] = 11}, {["name"] = "default:wood", ["y"] = 10, ["z"] = 15, ["x"] = 11}, {["name"] = "default:wood", ["y"] = 10, ["z"] = 16, ["x"] = 11}, {["name"] = "wool:red", ["y"] = 11, ["z"] = 2, ["x"] = 11}, {["name"] = "wool:white", ["y"] = 11, ["z"] = 3, ["x"] = 11}, {["name"] = "wool:white", ["y"] = 11, ["z"] = 4, ["x"] = 11}, {["name"] = "wool:white", ["y"] = 11, ["z"] = 5, ["x"] = 11}, {["name"] = "wool:white", ["y"] = 11, ["z"] = 6, ["x"] = 11}, {["name"] = "wool:white", ["y"] = 11, ["z"] = 7, ["x"] = 11}, {["name"] = "wool:white", ["y"] = 11, ["z"] = 8, ["x"] = 11}, {["name"] = "wool:white", ["y"] = 11, ["z"] = 9, ["x"] = 11}, {["name"] = "wool:white", ["y"] = 11, ["z"] = 10, ["x"] = 11}, {["name"] = "wool:white", ["y"] = 11, ["z"] = 11, ["x"] = 11}, {["name"] = "wool:red", ["y"] = 11, ["z"] = 12, ["x"] = 11}, {["name"] = "stairs:slab_sandstone", ["y"] = 12, ["z"] = 3, ["param1"] = 14, ["param2"] = 1, ["x"] = 11}, {["name"] = "stairs:slab_sandstone", ["y"] = 12, ["z"] = 4, ["param1"] = 14, ["param2"] = 1, ["x"] = 11}, {["name"] = "stairs:slab_sandstone", ["y"] = 12, ["z"] = 5, ["param1"] = 14, ["param2"] = 1, ["x"] = 11}, {["name"] = "stairs:slab_sandstone", ["y"] = 12, ["z"] = 6, ["param1"] = 14, ["param2"] = 1, ["x"] = 11}, {["name"] = "stairs:slab_sandstone", ["y"] = 12, ["z"] = 7, ["param1"] = 14, ["param2"] = 1, ["x"] = 11}, {["name"] = "stairs:slab_sandstone", ["y"] = 12, ["z"] = 8, ["param1"] = 14, ["param2"] = 1, ["x"] = 11}, {["name"] = "stairs:slab_sandstone", ["y"] = 12, ["z"] = 9, ["param1"] = 14, ["param2"] = 1, ["x"] = 11}, {["name"] = "stairs:slab_sandstone", ["y"] = 12, ["z"] = 10, ["param1"] = 14, ["param2"] = 1, ["x"] = 11}, {["name"] = "stairs:slab_sandstone", ["y"] = 12, ["z"] = 11, ["param1"] = 14, ["param2"] = 1, ["x"] = 11}, {["name"] = "default:wood", ["y"] = 10, ["z"] = 0, ["x"] = 12}, {["name"] = "default:wood", ["y"] = 10, ["z"] = 1, ["x"] = 12}, {["name"] = "default:wood", ["y"] = 10, ["z"] = 2, ["x"] = 12}, {["name"] = "default:wood", ["y"] = 10, ["z"] = 3, ["x"] = 12}, {["name"] = "default:wood", ["y"] = 10, ["z"] = 4, ["x"] = 12}, {["name"] = "default:wood", ["y"] = 10, ["z"] = 5, ["x"] = 12}, {["name"] = "default:wood", ["y"] = 10, ["z"] = 6, ["x"] = 12}, {["name"] = "default:wood", ["y"] = 10, ["z"] = 7, ["x"] = 12}, {["name"] = "default:wood", ["y"] = 10, ["z"] = 8, ["x"] = 12}, {["name"] = "default:wood", ["y"] = 10, ["z"] = 9, ["x"] = 12}, {["name"] = "default:wood", ["y"] = 10, ["z"] = 10, ["x"] = 12}, {["name"] = "default:wood", ["y"] = 10, ["z"] = 11, ["x"] = 12}, {["name"] = "default:wood", ["y"] = 10, ["z"] = 12, ["x"] = 12}, {["name"] = "default:wood", ["y"] = 10, ["z"] = 13, ["x"] = 12}, {["name"] = "default:wood", ["y"] = 10, ["z"] = 14, ["x"] = 12}, {["name"] = "default:wood", ["y"] = 10, ["z"] = 15, ["x"] = 12}, {["name"] = "default:wood", ["y"] = 10, ["z"] = 16, ["x"] = 12}, {["name"] = "wool:red", ["y"] = 11, ["z"] = 2, ["x"] = 12}, {["name"] = "wool:white", ["y"] = 11, ["z"] = 3, ["x"] = 12}, {["name"] = "wool:white", ["y"] = 11, ["z"] = 4, ["x"] = 12}, {["name"] = "wool:white", ["y"] = 11, ["z"] = 5, ["x"] = 12}, {["name"] = "wool:white", ["y"] = 11, ["z"] = 6, ["x"] = 12}, {["name"] = "wool:white", ["y"] = 11, ["z"] = 7, ["x"] = 12}, {["name"] = "wool:white", ["y"] = 11, ["z"] = 8, ["x"] = 12}, {["name"] = "wool:white", ["y"] = 11, ["z"] = 9, ["x"] = 12}, {["name"] = "wool:white", ["y"] = 11, ["z"] = 10, ["x"] = 12}, {["name"] = "wool:white", ["y"] = 11, ["z"] = 11, ["x"] = 12}, {["name"] = "wool:red", ["y"] = 11, ["z"] = 12, ["x"] = 12}, {["name"] = "stairs:slab_sandstone", ["y"] = 12, ["z"] = 3, ["param1"] = 14, ["param2"] = 1, ["x"] = 12}, {["name"] = "stairs:slab_sandstone", ["y"] = 12, ["z"] = 4, ["param1"] = 14, ["x"] = 12}, {["name"] = "stairs:slab_sandstone", ["y"] = 12, ["z"] = 5, ["param1"] = 14, ["x"] = 12}, {["name"] = "stairs:slab_sandstone", ["y"] = 12, ["z"] = 6, ["param1"] = 14, ["x"] = 12}, {["name"] = "stairs:slab_sandstone", ["y"] = 12, ["z"] = 7, ["param1"] = 14, ["x"] = 12}, {["name"] = "stairs:slab_sandstone", ["y"] = 12, ["z"] = 8, ["param1"] = 14, ["x"] = 12}, {["name"] = "stairs:slab_sandstone", ["y"] = 12, ["z"] = 9, ["param1"] = 14, ["x"] = 12}, {["name"] = "stairs:slab_sandstone", ["y"] = 12, ["z"] = 10, ["param1"] = 14, ["x"] = 12}, {["name"] = "stairs:slab_sandstone", ["y"] = 12, ["z"] = 11, ["param1"] = 14, ["x"] = 12}, {["name"] = "default:wood", ["y"] = 10, ["z"] = 0, ["x"] = 13}, {["name"] = "default:wood", ["y"] = 10, ["z"] = 1, ["x"] = 13}, {["name"] = "default:wood", ["y"] = 10, ["z"] = 2, ["x"] = 13}, {["name"] = "default:wood", ["y"] = 10, ["z"] = 3, ["x"] = 13}, {["name"] = "default:wood", ["y"] = 10, ["z"] = 4, ["x"] = 13}, {["name"] = "default:wood", ["y"] = 10, ["z"] = 5, ["x"] = 13}, {["name"] = "default:wood", ["y"] = 10, ["z"] = 6, ["x"] = 13}, {["name"] = "default:wood", ["y"] = 10, ["z"] = 7, ["x"] = 13}, {["name"] = "default:wood", ["y"] = 10, ["z"] = 8, ["x"] = 13}, {["name"] = "default:wood", ["y"] = 10, ["z"] = 9, ["x"] = 13}, {["name"] = "default:wood", ["y"] = 10, ["z"] = 10, ["x"] = 13}, {["name"] = "default:wood", ["y"] = 10, ["z"] = 11, ["x"] = 13}, {["name"] = "default:wood", ["y"] = 10, ["z"] = 12, ["x"] = 13}, {["name"] = "default:wood", ["y"] = 10, ["z"] = 13, ["x"] = 13}, {["name"] = "default:wood", ["y"] = 10, ["z"] = 14, ["x"] = 13}, {["name"] = "default:wood", ["y"] = 10, ["z"] = 15, ["x"] = 13}, {["name"] = "default:wood", ["y"] = 10, ["z"] = 16, ["x"] = 13}, {["name"] = "wool:red", ["y"] = 11, ["z"] = 2, ["x"] = 13}, {["name"] = "wool:white", ["y"] = 11, ["z"] = 3, ["x"] = 13}, {["name"] = "wool:white", ["y"] = 11, ["z"] = 4, ["x"] = 13}, {["name"] = "wool:white", ["y"] = 11, ["z"] = 5, ["x"] = 13}, {["name"] = "wool:white", ["y"] = 11, ["z"] = 6, ["x"] = 13}, {["name"] = "wool:white", ["y"] = 11, ["z"] = 7, ["x"] = 13}, {["name"] = "wool:white", ["y"] = 11, ["z"] = 8, ["x"] = 13}, {["name"] = "wool:white", ["y"] = 11, ["z"] = 9, ["x"] = 13}, {["name"] = "wool:white", ["y"] = 11, ["z"] = 10, ["x"] = 13}, {["name"] = "wool:white", ["y"] = 11, ["z"] = 11, ["x"] = 13}, {["name"] = "wool:red", ["y"] = 11, ["z"] = 12, ["x"] = 13}, {["name"] = "stairs:slab_sandstone", ["y"] = 12, ["z"] = 3, ["param1"] = 14, ["param2"] = 1, ["x"] = 13}, {["name"] = "stairs:slab_sandstone", ["y"] = 12, ["z"] = 4, ["param1"] = 14, ["param2"] = 1, ["x"] = 13}, {["name"] = "stairs:slab_sandstone", ["y"] = 12, ["z"] = 5, ["param1"] = 14, ["x"] = 13}, {["name"] = "stairs:slab_sandstone", ["y"] = 12, ["z"] = 6, ["param1"] = 14, ["x"] = 13}, {["name"] = "stairs:slab_sandstone", ["y"] = 12, ["z"] = 7, ["param1"] = 14, ["x"] = 13}, {["name"] = "stairs:slab_sandstone", ["y"] = 12, ["z"] = 8, ["param1"] = 14, ["x"] = 13}, {["name"] = "stairs:slab_sandstone", ["y"] = 12, ["z"] = 9, ["param1"] = 14, ["x"] = 13}, {["name"] = "stairs:slab_sandstone", ["y"] = 12, ["z"] = 10, ["param1"] = 14, ["x"] = 13}, {["name"] = "stairs:slab_sandstone", ["y"] = 12, ["z"] = 11, ["param1"] = 14, ["x"] = 13}, {["name"] = "default:wood", ["y"] = 10, ["z"] = 0, ["x"] = 14}, {["name"] = "default:wood", ["y"] = 10, ["z"] = 1, ["x"] = 14}, {["name"] = "default:wood", ["y"] = 10, ["z"] = 2, ["x"] = 14}, {["name"] = "default:wood", ["y"] = 10, ["z"] = 3, ["x"] = 14}, {["name"] = "default:wood", ["y"] = 10, ["z"] = 4, ["x"] = 14}, {["name"] = "default:wood", ["y"] = 10, ["z"] = 5, ["x"] = 14}, {["name"] = "default:wood", ["y"] = 10, ["z"] = 6, ["x"] = 14}, {["name"] = "default:wood", ["y"] = 10, ["z"] = 7, ["x"] = 14}, {["name"] = "default:wood", ["y"] = 10, ["z"] = 8, ["x"] = 14}, {["name"] = "default:wood", ["y"] = 10, ["z"] = 9, ["x"] = 14}, {["name"] = "default:wood", ["y"] = 10, ["z"] = 10, ["x"] = 14}, {["name"] = "default:wood", ["y"] = 10, ["z"] = 11, ["x"] = 14}, {["name"] = "default:wood", ["y"] = 10, ["z"] = 12, ["x"] = 14}, {["name"] = "default:wood", ["y"] = 10, ["z"] = 13, ["x"] = 14}, {["name"] = "default:wood", ["y"] = 10, ["z"] = 14, ["x"] = 14}, {["name"] = "default:wood", ["y"] = 10, ["z"] = 15, ["x"] = 14}, {["name"] = "default:wood", ["y"] = 10, ["z"] = 16, ["x"] = 14}, {["name"] = "wool:red", ["y"] = 11, ["z"] = 2, ["x"] = 14}, {["name"] = "wool:white", ["y"] = 11, ["z"] = 3, ["x"] = 14}, {["name"] = "wool:white", ["y"] = 11, ["z"] = 4, ["x"] = 14}, {["name"] = "wool:white", ["y"] = 11, ["z"] = 5, ["x"] = 14}, {["name"] = "wool:white", ["y"] = 11, ["z"] = 6, ["x"] = 14}, {["name"] = "wool:white", ["y"] = 11, ["z"] = 7, ["x"] = 14}, {["name"] = "wool:white", ["y"] = 11, ["z"] = 8, ["x"] = 14}, {["name"] = "wool:white", ["y"] = 11, ["z"] = 9, ["x"] = 14}, {["name"] = "wool:white", ["y"] = 11, ["z"] = 10, ["x"] = 14}, {["name"] = "wool:white", ["y"] = 11, ["z"] = 11, ["x"] = 14}, {["name"] = "wool:red", ["y"] = 11, ["z"] = 12, ["x"] = 14}, {["name"] = "stairs:slab_sandstone", ["y"] = 12, ["z"] = 3, ["param1"] = 14, ["param2"] = 1, ["x"] = 14}, {["name"] = "stairs:slab_sandstone", ["y"] = 12, ["z"] = 4, ["param1"] = 14, ["param2"] = 1, ["x"] = 14}, {["name"] = "stairs:slab_sandstone", ["y"] = 12, ["z"] = 5, ["param1"] = 14, ["x"] = 14}, {["name"] = "stairs:slab_sandstone", ["y"] = 12, ["z"] = 6, ["param1"] = 14, ["x"] = 14}, {["name"] = "stairs:slab_sandstone", ["y"] = 12, ["z"] = 7, ["param1"] = 14, ["x"] = 14}, {["name"] = "stairs:slab_sandstone", ["y"] = 12, ["z"] = 8, ["param1"] = 14, ["param2"] = 1, ["x"] = 14}, {["name"] = "stairs:slab_sandstone", ["y"] = 12, ["z"] = 9, ["param1"] = 14, ["x"] = 14}, {["name"] = "stairs:slab_sandstone", ["y"] = 12, ["z"] = 10, ["param1"] = 14, ["x"] = 14}, {["name"] = "stairs:slab_sandstone", ["y"] = 12, ["z"] = 11, ["param1"] = 14, ["x"] = 14}, {["name"] = "default:wood", ["y"] = 0, ["z"] = 0, ["x"] = 15}, {["name"] = "default:wood", ["y"] = 0, ["z"] = 1, ["x"] = 15}, {["name"] = "default:wood", ["y"] = 0, ["z"] = 15, ["x"] = 15}, {["name"] = "default:wood", ["y"] = 0, ["z"] = 16, ["x"] = 15}, {["name"] = "default:wood", ["y"] = 1, ["z"] = 0, ["x"] = 15}, {["name"] = "default:wood", ["y"] = 1, ["z"] = 1, ["x"] = 15}, {["name"] = "default:wood", ["y"] = 1, ["z"] = 15, ["x"] = 15}, {["name"] = "default:wood", ["y"] = 1, ["z"] = 16, ["x"] = 15}, {["name"] = "default:wood", ["y"] = 2, ["z"] = 0, ["x"] = 15}, {["name"] = "default:wood", ["y"] = 2, ["z"] = 1, ["x"] = 15}, {["name"] = "default:wood", ["y"] = 2, ["z"] = 15, ["x"] = 15}, {["name"] = "default:wood", ["y"] = 2, ["z"] = 16, ["x"] = 15}, {["name"] = "default:wood", ["y"] = 3, ["z"] = 0, ["x"] = 15}, {["name"] = "default:wood", ["y"] = 3, ["z"] = 1, ["x"] = 15}, {["name"] = "default:wood", ["y"] = 3, ["z"] = 15, ["x"] = 15}, {["name"] = "default:wood", ["y"] = 3, ["z"] = 16, ["x"] = 15}, {["name"] = "default:wood", ["y"] = 4, ["z"] = 0, ["x"] = 15}, {["name"] = "default:wood", ["y"] = 4, ["z"] = 1, ["x"] = 15}, {["name"] = "default:wood", ["y"] = 4, ["z"] = 15, ["x"] = 15}, {["name"] = "default:wood", ["y"] = 4, ["z"] = 16, ["x"] = 15}, {["name"] = "default:wood", ["y"] = 5, ["z"] = 0, ["x"] = 15}, {["name"] = "default:wood", ["y"] = 5, ["z"] = 1, ["x"] = 15}, {["name"] = "default:wood", ["y"] = 5, ["z"] = 15, ["x"] = 15}, {["name"] = "default:wood", ["y"] = 5, ["z"] = 16, ["x"] = 15}, {["name"] = "default:wood", ["y"] = 6, ["z"] = 0, ["x"] = 15}, {["name"] = "default:wood", ["y"] = 6, ["z"] = 1, ["x"] = 15}, {["name"] = "default:wood", ["y"] = 6, ["z"] = 15, ["x"] = 15}, {["name"] = "default:wood", ["y"] = 6, ["z"] = 16, ["x"] = 15}, {["name"] = "default:wood", ["y"] = 7, ["z"] = 0, ["x"] = 15}, {["name"] = "default:wood", ["y"] = 7, ["z"] = 1, ["x"] = 15}, {["name"] = "default:wood", ["y"] = 7, ["z"] = 15, ["x"] = 15}, {["name"] = "default:wood", ["y"] = 7, ["z"] = 16, ["x"] = 15}, {["name"] = "default:wood", ["y"] = 8, ["z"] = 0, ["x"] = 15}, {["name"] = "default:wood", ["y"] = 8, ["z"] = 1, ["x"] = 15}, {["name"] = "default:wood", ["y"] = 8, ["z"] = 15, ["x"] = 15}, {["name"] = "default:wood", ["y"] = 8, ["z"] = 16, ["x"] = 15}, {["name"] = "default:wood", ["y"] = 9, ["z"] = 0, ["x"] = 15}, {["name"] = "default:wood", ["y"] = 9, ["z"] = 1, ["x"] = 15}, {["name"] = "default:wood", ["y"] = 9, ["z"] = 15, ["x"] = 15}, {["name"] = "default:wood", ["y"] = 9, ["z"] = 16, ["x"] = 15}, {["name"] = "default:wood", ["y"] = 10, ["z"] = 0, ["x"] = 15}, {["name"] = "default:wood", ["y"] = 10, ["z"] = 1, ["x"] = 15}, {["name"] = "default:wood", ["y"] = 10, ["z"] = 2, ["x"] = 15}, {["name"] = "default:wood", ["y"] = 10, ["z"] = 3, ["x"] = 15}, {["name"] = "default:wood", ["y"] = 10, ["z"] = 4, ["x"] = 15}, {["name"] = "default:wood", ["y"] = 10, ["z"] = 5, ["x"] = 15}, {["name"] = "default:wood", ["y"] = 10, ["z"] = 6, ["x"] = 15}, {["name"] = "default:wood", ["y"] = 10, ["z"] = 7, ["x"] = 15}, {["name"] = "default:wood", ["y"] = 10, ["z"] = 8, ["x"] = 15}, {["name"] = "default:wood", ["y"] = 10, ["z"] = 9, ["x"] = 15}, {["name"] = "default:wood", ["y"] = 10, ["z"] = 10, ["x"] = 15}, {["name"] = "default:wood", ["y"] = 10, ["z"] = 11, ["x"] = 15}, {["name"] = "default:wood", ["y"] = 10, ["z"] = 12, ["x"] = 15}, {["name"] = "default:wood", ["y"] = 10, ["z"] = 13, ["x"] = 15}, {["name"] = "default:wood", ["y"] = 10, ["z"] = 14, ["x"] = 15}, {["name"] = "default:wood", ["y"] = 10, ["z"] = 15, ["x"] = 15}, {["name"] = "default:wood", ["y"] = 10, ["z"] = 16, ["x"] = 15}, {["name"] = "wool:red", ["y"] = 11, ["z"] = 2, ["x"] = 15}, {["name"] = "wool:red", ["y"] = 11, ["z"] = 3, ["x"] = 15}, {["name"] = "wool:red", ["y"] = 11, ["z"] = 4, ["x"] = 15}, {["name"] = "wool:red", ["y"] = 11, ["z"] = 5, ["x"] = 15}, {["name"] = "wool:red", ["y"] = 11, ["z"] = 6, ["x"] = 15}, {["name"] = "wool:red", ["y"] = 11, ["z"] = 7, ["x"] = 15}, {["name"] = "wool:red", ["y"] = 11, ["z"] = 8, ["x"] = 15}, {["name"] = "wool:red", ["y"] = 11, ["z"] = 9, ["x"] = 15}, {["name"] = "wool:red", ["y"] = 11, ["z"] = 10, ["x"] = 15}, {["name"] = "wool:red", ["y"] = 11, ["z"] = 11, ["x"] = 15}, {["name"] = "wool:red", ["y"] = 11, ["z"] = 12, ["x"] = 15}, {["name"] = "default:wood", ["y"] = 0, ["z"] = 0, ["x"] = 16}, {["name"] = "default:wood", ["y"] = 0, ["z"] = 1, ["x"] = 16}, {["name"] = "default:wood", ["y"] = 0, ["z"] = 15, ["x"] = 16}, {["name"] = "default:wood", ["y"] = 0, ["z"] = 16, ["x"] = 16}, {["name"] = "default:wood", ["y"] = 1, ["z"] = 0, ["x"] = 16}, {["name"] = "default:wood", ["y"] = 1, ["z"] = 1, ["x"] = 16}, {["name"] = "default:wood", ["y"] = 1, ["z"] = 15, ["x"] = 16}, {["name"] = "default:wood", ["y"] = 1, ["z"] = 16, ["x"] = 16}, {["name"] = "default:wood", ["y"] = 2, ["z"] = 0, ["x"] = 16}, {["name"] = "default:wood", ["y"] = 2, ["z"] = 1, ["x"] = 16}, {["name"] = "default:wood", ["y"] = 2, ["z"] = 15, ["x"] = 16}, {["name"] = "default:wood", ["y"] = 2, ["z"] = 16, ["x"] = 16}, {["name"] = "default:wood", ["y"] = 3, ["z"] = 0, ["x"] = 16}, {["name"] = "default:wood", ["y"] = 3, ["z"] = 1, ["x"] = 16}, {["name"] = "default:wood", ["y"] = 3, ["z"] = 15, ["x"] = 16}, {["name"] = "default:wood", ["y"] = 3, ["z"] = 16, ["x"] = 16}, {["name"] = "default:wood", ["y"] = 4, ["z"] = 0, ["x"] = 16}, {["name"] = "default:wood", ["y"] = 4, ["z"] = 1, ["x"] = 16}, {["name"] = "default:wood", ["y"] = 4, ["z"] = 15, ["x"] = 16}, {["name"] = "default:wood", ["y"] = 4, ["z"] = 16, ["x"] = 16}, {["name"] = "default:wood", ["y"] = 5, ["z"] = 0, ["x"] = 16}, {["name"] = "default:wood", ["y"] = 5, ["z"] = 1, ["x"] = 16}, {["name"] = "default:wood", ["y"] = 5, ["z"] = 15, ["x"] = 16}, {["name"] = "default:wood", ["y"] = 5, ["z"] = 16, ["x"] = 16}, {["name"] = "default:wood", ["y"] = 6, ["z"] = 0, ["x"] = 16}, {["name"] = "default:wood", ["y"] = 6, ["z"] = 1, ["x"] = 16}, {["name"] = "default:wood", ["y"] = 6, ["z"] = 15, ["x"] = 16}, {["name"] = "default:wood", ["y"] = 6, ["z"] = 16, ["x"] = 16}, {["name"] = "default:wood", ["y"] = 7, ["z"] = 0, ["x"] = 16}, {["name"] = "default:wood", ["y"] = 7, ["z"] = 1, ["x"] = 16}, {["name"] = "default:wood", ["y"] = 7, ["z"] = 15, ["x"] = 16}, {["name"] = "default:wood", ["y"] = 7, ["z"] = 16, ["x"] = 16}, {["name"] = "default:wood", ["y"] = 8, ["z"] = 0, ["x"] = 16}, {["name"] = "default:wood", ["y"] = 8, ["z"] = 1, ["x"] = 16}, {["name"] = "default:wood", ["y"] = 8, ["z"] = 15, ["x"] = 16}, {["name"] = "default:wood", ["y"] = 8, ["z"] = 16, ["x"] = 16}, {["name"] = "default:wood", ["y"] = 9, ["z"] = 0, ["x"] = 16}, {["name"] = "default:wood", ["y"] = 9, ["z"] = 1, ["x"] = 16}, {["name"] = "default:wood", ["y"] = 9, ["z"] = 15, ["x"] = 16}, {["name"] = "default:wood", ["y"] = 9, ["z"] = 16, ["x"] = 16}, {["name"] = "default:wood", ["y"] = 10, ["z"] = 0, ["x"] = 16}, {["name"] = "default:wood", ["y"] = 10, ["z"] = 1, ["x"] = 16}, {["name"] = "default:wood", ["y"] = 10, ["z"] = 2, ["x"] = 16}, {["name"] = "default:wood", ["y"] = 10, ["z"] = 3, ["x"] = 16}, {["name"] = "default:wood", ["y"] = 10, ["z"] = 4, ["x"] = 16}, {["name"] = "default:wood", ["y"] = 10, ["z"] = 5, ["x"] = 16}, {["name"] = "default:wood", ["y"] = 10, ["z"] = 6, ["x"] = 16}, {["name"] = "default:wood", ["y"] = 10, ["z"] = 7, ["x"] = 16}, {["name"] = "default:wood", ["y"] = 10, ["z"] = 8, ["x"] = 16}, {["name"] = "default:wood", ["y"] = 10, ["z"] = 9, ["x"] = 16}, {["name"] = "default:wood", ["y"] = 10, ["z"] = 10, ["x"] = 16}, {["name"] = "default:wood", ["y"] = 10, ["z"] = 11, ["x"] = 16}, {["name"] = "default:wood", ["y"] = 10, ["z"] = 12, ["x"] = 16}, {["name"] = "default:wood", ["y"] = 10, ["z"] = 13, ["x"] = 16}, {["name"] = "default:wood", ["y"] = 10, ["z"] = 14, ["x"] = 16}, {["name"] = "default:wood", ["y"] = 10, ["z"] = 15, ["x"] = 16}, {["name"] = "default:wood", ["y"] = 10, ["z"] = 16, ["x"] = 16}}